Workbook

Sheet Təlimat
A1: Kütlə planı · Bolonya — necə istifadə etmək
A3: 1. “Gündəlik” vərəqində hər yediyini bir sətirə yaz: Tarix, Yemək, Məhsul (siyahıdan seç), Qram. kkal və makrolar avtomatik hesablanır.
A4: 2. “Günlər” vərəqində həmin günün tipini seç (Zal / İstirahət) və tennis oynamısansa dəqiqəni yaz. Norma avtomatik dəyişir.
A5: 3. Səhər çəkisini “Günlər” vərəqinin “Çəki” sütununa yaz (həftədə ən azı 4 dəfə).
A6: 4. “Həftəlik” vərəqi orta kalorini, proteini və çəki dəyişməsini göstərir, normanı artırmaq/azaltmaq lazımdırsa deyir.
A7: 5. Çəki dəyişəndə “Profil” vərəqində çəkini yenilə — bütün normalar yenidən hesablanır.
A9: Rənglər: göy rəqəm = sənin dəyişə biləcəyin giriş xanası; sarı fon = doldurmalı olduğun xana; qara = formula (toxunma).
A10: “Gündəlik” vərəqindəki ilk sətirlər nümunədir (9 oktyabr, Cümə menyusu). Yediyinə görə dəyiş və ya sil.
A11: Öz məhsulunu “Qida bazası” vərəqinin sonundakı boş sarı sətirlərə əlavə et (qablaşdırmadakı “per 100 g” dəyərləri).
A13: Qida dəyərləri: CREA (İtaliya qida cədvəlləri), USDA FoodData Central və İtaliya supermarket etiketlərinə əsaslanan orta rəqəmlərdir; məhsuldan məhsula ±10% fərq ola bilər.
A14: Qiymətlər Bolonya supermarketləri (Lidl, Conad, Coop, Esselunga) üçün təxminidir, 2026.
A15: Bu plan tibbi məsləhət deyil. Sağlamlıq problemin varsa, həkimlə məsləhətləş.

Sheet Profil
A1: Profil və hesablama
A3: Giriş
A4: Çəki, kq | B4: 58.3 | C4: Səhər, ac qarına
A5: Boy, sm | B5: 165
A6: Yaş | B6: 21 | C6: Sənin dediyin: 18–24 yaş; 21 götürülüb — dəqiq yaşını yaz
A7: Aktivlik əmsalı (məşqsiz) | B7: 1.4 | C7: 1,3 çox az hərəkət · 1,4 tələbə, piyada gəzir · 1,5 ayaq üstə iş
A8: Kütlə üçün artıq kalori, kkal | B8: 300 | C8: Həftəlik çəki artımına görə ±150 dəyiş
A9: Zal məşqi (≈60 dəq), kkal | B9: 250 | C9: Güc məşqi ≈ (MET 5 − 1) × çəki × saat
A10: Protein, q/kq | B10: 2 | C10: Əzələ artımı üçün 1,6–2,2
A11: Yağ, kalorinin payı | B11: 0.25 | C11: 20–30%
A13: Nəticə
A14: Bazal metabolizm (BMR), kkal | B14: =ROUND(10*B4+6.25*B5-5*B6+5,0) | C14: Mifflin–St Jeor, kişi
A15: Gündəlik xərc, məşqsiz, kkal | B15: =ROUND((10*B4+6.25*B5-5*B6+5)*B7,0) | C15: BMR × aktivlik
A16: İstirahət günü norması, kkal | B16: =ROUND(((10*B4+6.25*B5-5*B6+5)*B7+B8)/10,0)*10 | C16: xərc + artıq
A17: Zal günü norması, kkal | B17: =ROUND(((10*B4+6.25*B5-5*B6+5)*B7+B8+B9)/10,0)*10 | C17: xərc + artıq + məşq
A18: Tennis tək, 60 dəq, kkal | B18: =ROUND(7*B4,0) | C18: (MET 8 − 1) × çəki
A19: Tennis cüt, 60 dəq, kkal | B19: =ROUND(5*B4,0) | C19: (MET 6 − 1) × çəki
A20: Protein, minimum q/gün | B20: =ROUND(B10*B4,0)
A21: Yağ, istirahət / zal, q | B21: =ROUND(B16*B11/9,0)&" / "&ROUND(B17*B11/9,0)
A22: Karbohidrat, istirahət, q | B22: =ROUND((B16-B20*4-ROUND(B16*B11/9,0)*9)/4,0) | C22: qalan kalori
A23: Karbohidrat, zal, q | B23: =ROUND((B17-B20*4-ROUND(B17*B11/9,0)*9)/4,0)
A24: Su, l/gün | B24: 2,5–3 | C24: tennis/zal günü +0,5–1 l
A25: Hədəf çəki artımı, kq/həftə | B25: 0,2–0,3 | C25: təmiz kütlə

Sheet Qida bazası
A1: Məhsul (italyanca) | B1: İtalyanca | C1: Qrup | D1: kkal / 100 q | E1: Protein, q | F1: Karbohidrat, q | G1: Yağ, q | H1: Porsiya
A2: Yulaf yarması (fiocchi d'avena) | B2: fiocchi d'avena | C2: Taxıl | D2: 372 | E2: 13.5 | F2: 58.7 | G2: 7 | H2: 1 xörək qaşığı ≈ 10 q
A3: Süd 1,5% (latte parzialmente scremato) | B3: latte parzialmente scremato | C3: Süd | D3: 46 | E3: 3.3 | F3: 4.9 | G3: 1.6 | H3: 1 stəkan ≈ 250 q
A4: Süd 3,5% (latte intero) | B4: latte intero | C4: Süd | D4: 64 | E4: 3.3 | F4: 4.8 | G4: 3.6 | H4: 1 stəkan ≈ 250 q
A5: Kefir (kefir) | B5: kefir | C5: Süd | D5: 60 | E5: 3.5 | F5: 4.5 | G5: 3 | H5: 1 stəkan ≈ 250 q
A6: Yunan yoqurtu 0% (yogurt greco 0%) | B6: yogurt greco 0% | C6: Süd | D6: 57 | E6: 10 | F6: 4 | G6: 0 | H6: 1 qutu ≈ 170 q
A7: Yunan yoqurtu 2% (yogurt greco 2%) | B7: yogurt greco 2% | C7: Süd | D7: 73 | E7: 10 | F7: 3 | G7: 2 | H7: 1 qutu ≈ 170 q
A8: Skyr (skyr) | B8: skyr | C8: Süd | D8: 63 | E8: 11 | F8: 4 | G8: 0.2 | H8: 1 qutu ≈ 150 q
A9: Dənəli kəsmik (fiocchi di latte) | B9: fiocchi di latte | C9: Süd | D9: 100 | E9: 12 | F9: 3 | G9: 4.5 | H9: 1 qutu ≈ 150 q
A10: Rikotta (ricotta vaccina) | B10: ricotta vaccina | C10: Süd | D10: 146 | E10: 8.8 | F10: 3.5 | G10: 10.9 | H10: 1 qutu ≈ 250 q
A11: Motsarella (mozzarella) | B11: mozzarella | C11: Süd | D11: 253 | E11: 18.7 | F11: 0.7 | G11: 19.5 | H11: 1 top ≈ 125 q
A12: Parmezan (Parmigiano Reggiano) | B12: Parmigiano Reggiano | C12: Süd | D12: 392 | E12: 33 | F12: 0 | G12: 28 | H12: 1 xörək qaşığı rəndələnmiş ≈ 8 q
A13: Yumurta (uova) | B13: uova | C13: Protein | D13: 140 | E13: 12.5 | F13: 0.7 | G13: 9.5 | H13: 1 ədəd (L) ≈ 55 q
... A15: Toyuq döşü (çiy) (petto di pollo) | B15: petto di pollo | C15: Protein | D15: 105 | E15: 23 | F15: 0 | G15: 1.2 | H15: bişəndə ~25% yüngülləşir
A16: Hind toyuğu döşü (çiy) (fesa di tacchino) | B16: fesa di tacchino | C16: Protein | D16: 107 | E16: 24 | F16: 0 | G16: 1.2
A17: Mal qiyməsi 5% (çiy) (macinato magro di manzo) | B17: macinato magro di manzo | C17: Protein | D17: 137 | E17: 21 | F17: 0 | G17: 5.5
A18: Mal əti, yağsız (çiy) (fesa di manzo) | B18: fesa di manzo | C18: Protein | D18: 125 | E18: 22 | F18: 0 | G18: 4
A19: Bresaola (bresaola) | B19: bresaola | C19: Protein | D19: 151 | E19: 32 | F19: 0 | G19: 2.6 | H19: 1 dilim ≈ 10 q
A20: Bişmiş vetçina (prosciutto cotto) | B20: prosciutto cotto | C20: Protein | D20: 130 | E20: 19.5 | F20: 1 | G20: 5 | H20: 1 dilim ≈ 20 q
A21: Qurudulmuş vetçina (prosciutto crudo) | B21: prosciutto crudo | C21: Protein | D21: 268 | E21: 26 | F21: 0 | G21: 18 | H21: 1 dilim ≈ 15 q
A22: Mortadella (Bolonya) (mortadella) | B22: mortadella | C22: Protein | D22: 288 | E22: 15 | F22: 0 | G22: 25 | H22: 1 dilim ≈ 15 q
A23: Tuna, öz suyunda (tonno al naturale) | B23: tonno al naturale | C23: Protein | D23: 103 | E23: 24 | F23: 0 | G23: 0.8 | H23: 1 kiçik qutu süzülmüş ≈ 56–80 q
A24: Tuna, yağda (süzülmüş) (tonno sott'olio) | B24: tonno sott'olio | C24: Protein | D24: 192 | E24: 25.2 | F24: 0 | G24: 10.1
A25: Qızılbalıq (çiy) (salmone) | B25: salmone | C25: Protein | D25: 200 | E25: 20 | F25: 0 | G25: 13
A26: Treska (çiy) (merluzzo) | B26: merluzzo | C26: Protein | D26: 82 | E26: 17.8 | F26: 0 | G26: 0.7
A27: Krevet (çiy) (gamberi) | B27: gamberi | C27: Protein | D27: 85 | E27: 18 | F27: 0 | G27: 1
A28: Protein tozu (whey) (proteine whey) | B28: proteine whey | C28: Protein | D28: 380 | E28: 78 | F28: 6 | G28: 5 | H28: 1 ölçü qaşığı ≈ 30 q
A29: Makaron (çiy) (pasta di semola) | B29: pasta di semola | C29: Karbohidrat | D29: 357 | E29: 13 | F29: 71 | G29: 1.5 | H29: çiy çəki ilə yaz
A30: Tam taxıl makaron (çiy) (pasta integrale) | B30: pasta integrale | C30: Karbohidrat | D30: 340 | E30: 13.5 | F30: 64 | G30: 2.5 | H30: çiy çəki ilə yaz
A31: Makaron (bişmiş) (pasta cotta) | B31: pasta cotta | C31: Karbohidrat | D31: 158 | E31: 5.8 | F31: 31 | G31: 0.9
A32: Düyü (çiy) (riso) | B32: riso | C32: Karbohidrat | D32: 355 | E32: 7 | F32: 79 | G32: 0.6 | H32: çiy çəki ilə yaz
A33: Düyü (bişmiş) (riso cotto) | B33: riso cotto | C33: Karbohidrat | D33: 130 | E33: 2.7 | F33: 28 | G33: 0.3
A34: Kartof (patate) | B34: patate | C34: Karbohidrat | D34: 80 | E34: 2 | F34: 17.5 | G34: 0.1 | H34: 1 orta ≈ 170 q
A35: Batat (patata dolce) | B35: patata dolce | C35: Karbohidrat | D35: 86 | E35: 1.6 | F35: 20 | G35: 0.1
A36: Ağ çörək (pane comune) | B36: pane comune | C36: Karbohidrat | D36: 270 | E36: 8.5 | F36: 55 | G36: 1.5 | H36: 1 dilim ≈ 30 q
A37: Tam taxıl çörək (pane integrale) | B37: pane integrale | C37: Karbohidrat | D37: 240 | E37: 9 | F37: 46 | G37: 2.5 | H37: 1 dilim ≈ 30 q
A38: Piadina (piadina romagnola) | B38: piadina romagnola | C38: Karbohidrat | D38: 310 | E38: 8 | F38: 50 | G38: 9 | H38: 1 ədəd ≈ 110 q
A39: Düyü qalletası (gallette di riso) | B39: gallette di riso | C39: Karbohidrat | D39: 380 | E39: 8 | F39: 81 | G39: 2.8 | H39: 1 ədəd ≈ 8 q
A40: Kruasan (bar) (cornetto / brioche) | B40: cornetto / brioche | C40: Karbohidrat | D40: 410 | E40: 7 | F40: 48 | G40: 21 | H40: 1 ədəd ≈ 60 q
A41: Mərcimək (quru) (lenticchie secche) | B41: lenticchie secche | C41: Paxlalı | D41: 340 | E41: 24 | F41: 55 | G41: 1.5 | H41: quru çəki ilə yaz
...

Sheet Gündəlik
A1: Tarix | B1: Yemək | C1: Məhsul | D1: Qram | E1: kkal | F1: Protein | G1: Karb. | H1: Yağ | I1: Qeyd
A2: 46304 | B2: Səhər yeməyi | C2: Yumurta (uova) | D2: 110 | E2: =IF(OR(C2="",D2=""),"",IFERROR(INDEX('Qida bazası'!$D$2:$D$103,MATCH(C2,'Qida bazası'!$A$2:$A$103,0))*D2/100,"?")) | F2: =IF(OR(C2="",D2=""),"",IFERROR(INDEX('Qida bazası'!$E$2:$E$103,MATCH(C2,'Qida bazası'!$A$2:$A$103,0))*D2/100,"?")) | G2: =IF(OR(C2="",D2=""),"",IFERROR(INDEX('Qida bazası'!$F$2:$F$103,MATCH(C2,'Qida bazası'!$A$2:$A$103,0))*D2/100,"?")) | H2: =IF(OR(C2="",D2=""),"",IFERROR(INDEX('Qida bazası'!$G$2:$G$103,MATCH(C2,'Qida bazası'!$A$2:$A$103,0))*D2/100,"?")) | I2: nümunə — dəyiş və ya sil
A3: 46304 | B3: Səhər yeməyi | C3: Yumurta ağı (albume) | D3: 100 | E3: =IF(OR(C3="",D3=""),"",IFERROR(INDEX('Qida bazası'!$D$2:$D$103,MATCH(C3,'Qida bazası'!$A$2:$A$103,0))*D3/100,"?")) | F3: =IF(OR(C3="",D3=""),"",IFERROR(INDEX('Qida bazası'!$E$2:$E$103,MATCH(C3,'Qida bazası'!$A$2:$A$103,0))*D3/100,"?")) | G3: =IF(OR(C3="",D3=""),"",IFERROR(INDEX('Qida bazası'!$F$2:$F$103,MATCH(C3,'Qida bazası'!$A$2:$A$103,0))*D3/100,"?")) | H3: =IF(OR(C3="",D3=""),"",IFERROR(INDEX('Qida bazası'!$G$2:$G$103,MATCH(C3,'Qida bazası'!$A$2:$A$103,0))*D3/100,"?"))
A4: 46304 | B4: Səhər yeməyi | C4: Tam taxıl çörək (pane integrale) | D4: 100 | E4: =IF(OR(C4="",D4=""),"",IFERROR(INDEX('Qida bazası'!$D$2:$D$103,MATCH(C4,'Qida bazası'!$A$2:$A$103,0))*D4/100,"?")) | F4: =IF(OR(C4="",D4=""),"",IFERROR(INDEX('Qida bazası'!$E$2:$E$103,MATCH(C4,'Qida bazası'!$A$2:$A$103,0))*D4/100,"?")) | G4: =IF(OR(C4="",D4=""),"",IFERROR(INDEX('Qida bazası'!$F$2:$F$103,MATCH(C4,'Qida bazası'!$A$2:$A$103,0))*D4/100,"?")) | H4: =IF(OR(C4="",D4=""),"",IFERROR(INDEX('Qida bazası'!$G$2:$G$103,MATCH(C4,'Qida bazası'!$A$2:$A$103,0))*D4/100,"?"))
A5: 46304 | B5: Səhər yeməyi | C5: Portağal (arancia) | D5: 150 | E5: =IF(OR(C5="",D5=""),"",IFERROR(INDEX('Qida bazası'!$D$2:$D$103,MATCH(C5,'Qida bazası'!$A$2:$A$103,0))*D5/100,"?")) | F5: =IF(OR(C5="",D5=""),"",IFERROR(INDEX('Qida bazası'!$E$2:$E$103,MATCH(C5,'Qida bazası'!$A$2:$A$103,0))*D5/100,"?")) | G5: =IF(OR(C5="",D5=""),"",IFERROR(INDEX('Qida bazası'!$F$2:$F$103,MATCH(C5,'Qida bazası'!$A$2:$A$103,0))*D5/100,"?")) | H5: =IF(OR(C5="",D5=""),"",IFERROR(INDEX('Qida bazası'!$G$2:$G$103,MATCH(C5,'Qida bazası'!$A$2:$A$103,0))*D5/100,"?"))
A6: 46304 | B6: Səhər yeməyi | C6: Zeytun yağı (olio extravergine) | D6: 5 | E6: =IF(OR(C6="",D6=""),"",IFERROR(INDEX('Qida bazası'!$D$2:$D$103,MATCH(C6,'Qida bazası'!$A$2:$A$103,0))*D6/100,"?")) | F6: =IF(OR(C6="",D6=""),"",IFERROR(INDEX('Qida bazası'!$E$2:$E$103,MATCH(C6,'Qida bazası'!$A$2:$A$103,0))*D6/100,"?")) | G6: =IF(OR(C6="",D6=""),"",IFERROR(INDEX('Qida bazası'!$F$2:$F$103,MATCH(C6,'Qida bazası'!$A$2:$A$103,0))*D6/100,"?")) | H6: =IF(OR(C6="",D6=""),"",IFERROR(INDEX('Qida bazası'!$G$2:$G$103,MATCH(C6,'Qida bazası'!$A$2:$A$103,0))*D6/100,"?"))
A7: 46304 | B7: Qəlyanaltı 1 | C7: Yunan yoqurtu 0% (yogurt greco 0%) | D7: 170 | E7: =IF(OR(C7="",D7=""),"",IFERROR(INDEX('Qida bazası'!$D$2:$D$103,MATCH(C7,'Qida bazası'!$A$2:$A$103,0))*D7/100,"?")) | F7: =IF(OR(C7="",D7=""),"",IFERROR(INDEX('Qida bazası'!$E$2:$E$103,MATCH(C7,'Qida bazası'!$A$2:$A$103,0))*D7/100,"?")) | G7: =IF(OR(C7="",D7=""),"",IFERROR(INDEX('Qida bazası'!$F$2:$F$103,MATCH(C7,'Qida bazası'!$A$2:$A$103,0))*D7/100,"?")) | H7: =IF(OR(C7="",D7=""),"",IFERROR(INDEX('Qida bazası'!$G$2:$G$103,MATCH(C7,'Qida bazası'!$A$2:$A$103,0))*D7/100,"?"))
A8: 46304 | B8: Qəlyanaltı 1 | C8: Yulaf yarması (fiocchi d'avena) | D8: 60 | E8: =IF(OR(C8="",D8=""),"",IFERROR(INDEX('Qida bazası'!$D$2:$D$103,MATCH(C8,'Qida bazası'!$A$2:$A$103,0))*D8/100,"?")) | F8: =IF(OR(C8="",D8=""),"",IFERROR(INDEX('Qida bazası'!$E$2:$E$103,MATCH(C8,'Qida bazası'!$A$2:$A$103,0))*D8/100,"?")) | G8: =IF(OR(C8="",D8=""),"",IFERROR(INDEX('Qida bazası'!$F$2:$F$103,MATCH(C8,'Qida bazası'!$A$2:$A$103,0))*D8/100,"?")) | H8: =IF(OR(C8="",D8=""),"",IFERROR(INDEX('Qida bazası'!$G$2:$G$103,MATCH(C8,'Qida bazası'!$A$2:$A$103,0))*D8/100,"?"))
A9: 46304 | B9: Qəlyanaltı 1 | C9: Banan (banana) | D9: 120 | E9: =IF(OR(C9="",D9=""),"",IFERROR(INDEX('Qida bazası'!$D$2:$D$103,MATCH(C9,'Qida bazası'!$A$2:$A$103,0))*D9/100,"?")) | F9: =IF(OR(C9="",D9=""),"",IFERROR(INDEX('Qida bazası'!$E$2:$E$103,MATCH(C9,'Qida bazası'!$A$2:$A$103,0))*D9/100,"?")) | G9: =IF(OR(C9="",D9=""),"",IFERROR(INDEX('Qida bazası'!$F$2:$F$103,MATCH(C9,'Qida bazası'!$A$2:$A$103,0))*D9/100,"?")) | H9: =IF(OR(C9="",D9=""),"",IFERROR(INDEX('Qida bazası'!$G$2:$G$103,MATCH(C9,'Qida bazası'!$A$2:$A$103,0))*D9/100,"?"))
A10: 46304 | B10: Nahar | C10: Tagliatelle al ragù (hazır) (tagliatelle al ragù) | D10: 280 | E10: =IF(OR(C10="",D10=""),"",IFERROR(INDEX('Qida bazası'!$D$2:$D$103,MATCH(C10,'Qida bazası'!$A$2:$A$103,0))*D10/100,"?")) | F10: =IF(OR(C10="",D10=""),"",IFERROR(INDEX('Qida bazası'!$E$2:$E$103,MATCH(C10,'Qida bazası'!$A$2:$A$103,0))*D10/100,"?")) | G10: =IF(OR(C10="",D10=""),"",IFERROR(INDEX('Qida bazası'!$F$2:$F$103,MATCH(C10,'Qida bazası'!$A$2:$A$103,0))*D10/100,"?")) | H10: =IF(OR(C10="",D10=""),"",IFERROR(INDEX('Qida bazası'!$G$2:$G$103,MATCH(C10,'Qida bazası'!$A$2:$A$103,0))*D10/100,"?"))
A11: 46304 | B11: Nahar | C11: Yaşıl salat (insalata) | D11: 100 | E11: =IF(OR(C11="",D11=""),"",IFERROR(INDEX('Qida bazası'!$D$2:$D$103,MATCH(C11,'Qida bazası'!$A$2:$A$103,0))*D11/100,"?")) | F11: =IF(OR(C11="",D11=""),"",IFERROR(INDEX('Qida bazası'!$E$2:$E$103,MATCH(C11,'Qida bazası'!$A$2:$A$103,0))*D11/100,"?")) | G11: =IF(OR(C11="",D11=""),"",IFERROR(INDEX('Qida bazası'!$F$2:$F$103,MATCH(C11,'Qida bazası'!$A$2:$A$103,0))*D11/100,"?")) | H11: =IF(OR(C11="",D11=""),"",IFERROR(INDEX('Qida bazası'!$G$2:$G$103,MATCH(C11,'Qida bazası'!$A$2:$A$103,0))*D11/100,"?"))
A12: 46304 | B12: Nahar | C12: Zeytun yağı (olio extravergine) | D12: 5 | E12: =IF(OR(C12="",D12=""),"",IFERROR(INDEX('Qida bazası'!$D$2:$D$103,MATCH(C12,'Qida bazası'!$A$2:$A$103,0))*D12/100,"?")) | F12: =IF(OR(C12="",D12=""),"",IFERROR(INDEX('Qida bazası'!$E$2:$E$103,MATCH(C12,'Qida bazası'!$A$2:$A$103,0))*D12/100,"?")) | G12: =IF(OR(C12="",D12=""),"",IFERROR(INDEX('Qida bazası'!$F$2:$F$103,MATCH(C12,'Qida bazası'!$A$2:$A$103,0))*D12/100,"?")) | H12: =IF(OR(C12="",D12=""),"",IFERROR(INDEX('Qida bazası'!$G$2:$G$103,MATCH(C12,'Qida bazası'!$A$2:$A$103,0))*D12/100,"?"))
A13: 46304 | B13: Qəlyanaltı 2 | C13: Düyü qalletası (gallette di riso) | D13: 50 | E13: =IF(OR(C13="",D13=""),"",IFERROR(INDEX('Qida bazası'!$D$2:$D$103,MATCH(C13,'Qida bazası'!$A$2:$A$103,0))*D13/100,"?")) | F13: =IF(OR(C13="",D13=""),"",IFERROR(INDEX('Qida bazası'!$E$2:$E$103,MATCH(C13,'Qida bazası'!$A$2:$A$103,0))*D13/100,"?")) | G13: =IF(OR(C13="",D13=""),"",IFERROR(INDEX('Qida bazası'!$F$2:$F$103,MATCH(C13,'Qida bazası'!$A$2:$A$103,0))*D13/100,"?")) | H13: =IF(OR(C13="",D13=""),"",IFERROR(INDEX('Qida bazası'!$G$2:$G$103,MATCH(C13,'Qida bazası'!$A$2:$A$103,0))*D13/100,"?"))
A14: 46304 | B14: Qəlyanaltı 2 | C14: Bresaola (bresaola) | D14: 60 | E14: =IF(OR(C14="",D14=""),"",IFERROR(INDEX('Qida bazası'!$D$2:$D$103,MATCH(C14,'Qida bazası'!$A$2:$A$103,0))*D14/100,"?")) | F14: =IF(OR(C14="",D14=""),"",IFERROR(INDEX('Qida bazası'!$E$2:$E$103,MATCH(C14,'Qida bazası'!$A$2:$A$103,0))*D14/100,"?")) | G14: =IF(OR(C14="",D14=""),"",IFERROR(INDEX('Qida bazası'!$F$2:$F$103,MATCH(C14,'Qida bazası'!$A$2:$A$103,0))*D14/100,"?")) | H14: =IF(OR(C14="",D14=""),"",IFERROR(INDEX('Qida bazası'!$G$2:$G$103,MATCH(C14,'Qida bazası'!$A$2:$A$103,0))*D14/100,"?"))
... A19: 46304 | B19: Şam yeməyi | C19: Zeytun yağı (olio extravergine) | D19: 10 | E19: =IF(OR(C19="",D19=""),"",IFERROR(INDEX('Qida bazası'!$D$2:$D$103,MATCH(C19,'Qida bazası'!$A$2:$A$103,0))*D19/100,"?")) | F19: =IF(OR(C19="",D19=""),"",IFERROR(INDEX('Qida bazası'!$E$2:$E$103,MATCH(C19,'Qida bazası'!$A$2:$A$103,0))*D19/100,"?")) | G19: =IF(OR(C19="",D19=""),"",IFERROR(INDEX('Qida bazası'!$F$2:$F$103,MATCH(C19,'Qida bazası'!$A$2:$A$103,0))*D19/100,"?")) | H19: =IF(OR(C19="",D19=""),"",IFERROR(INDEX('Qida bazası'!$G$2:$G$103,MATCH(C19,'Qida bazası'!$A$2:$A$103,0))*D19/100,"?"))
E20: =IF(OR(C20="",D20=""),"",IFERROR(INDEX('Qida bazası'!$D$2:$D$103,MATCH(C20,'Qida bazası'!$A$2:$A$103,0))*D20/100,"?")) | F20: =IF(OR(C20="",D20=""),"",IFERROR(INDEX('Qida bazası'!$E$2:$E$103,MATCH(C20,'Qida bazası'!$A$2:$A$103,0))*D20/100,"?")) | G20: =IF(OR(C20="",D20=""),"",IFERROR(INDEX('Qida bazası'!$F$2:$F$103,MATCH(C20,'Qida bazası'!$A$2:$A$103,0))*D20/100,"?")) | H20: =IF(OR(C20="",D20=""),"",IFERROR(INDEX('Qida bazası'!$G$2:$G$103,MATCH(C20,'Qida bazası'!$A$2:$A$103,0))*D20/100,"?"))
E21: =IF(OR(C21="",D21=""),"",IFERROR(INDEX('Qida bazası'!$D$2:$D$103,MATCH(C21,'Qida bazası'!$A$2:$A$103,0))*D21/100,"?")) | F21: =IF(OR(C21="",D21=""),"",IFERROR(INDEX('Qida bazası'!$E$2:$E$103,MATCH(C21,'Qida bazası'!$A$2:$A$103,0))*D21/100,"?")) | G21: =IF(OR(C21="",D21=""),"",IFERROR(INDEX('Qida bazası'!$F$2:$F$103,MATCH(C21,'Qida bazası'!$A$2:$A$103,0))*D21/100,"?")) | H21: =IF(OR(C21="",D21=""),"",IFERROR(INDEX('Qida bazası'!$G$2:$G$103,MATCH(C21,'Qida bazası'!$A$2:$A$103,0))*D21/100,"?"))
E22: =IF(OR(C22="",D22=""),"",IFERROR(INDEX('Qida bazası'!$D$2:$D$103,MATCH(C22,'Qida bazası'!$A$2:$A$103,0))*D22/100,"?")) | F22: =IF(OR(C22="",D22=""),"",IFERROR(INDEX('Qida bazası'!$E$2:$E$103,MATCH(C22,'Qida bazası'!$A$2:$A$103,0))*D22/100,"?")) | G22: =IF(OR(C22="",D22=""),"",IFERROR(INDEX('Qida bazası'!$F$2:$F$103,MATCH(C22,'Qida bazası'!$A$2:$A$103,0))*D22/100,"?")) | H22: =IF(OR(C22="",D22=""),"",IFERROR(INDEX('Qida bazası'!$G$2:$G$103,MATCH(C22,'Qida bazası'!$A$2:$A$103,0))*D22/100,"?"))
E23: =IF(OR(C23="",D23=""),"",IFERROR(INDEX('Qida bazası'!$D$2:$D$103,MATCH(C23,'Qida bazası'!$A$2:$A$103,0))*D23/100,"?")) | F23: =IF(OR(C23="",D23=""),"",IFERROR(INDEX('Qida bazası'!$E$2:$E$103,MATCH(C23,'Qida bazası'!$A$2:$A$103,0))*D23/100,"?")) | G23: =IF(OR(C23="",D23=""),"",IFERROR(INDEX('Qida bazası'!$F$2:$F$103,MATCH(C23,'Qida bazası'!$A$2:$A$103,0))*D23/100,"?")) | H23: =IF(OR(C23="",D23=""),"",IFERROR(INDEX('Qida bazası'!$G$2:$G$103,MATCH(C23,'Qida bazası'!$A$2:$A$103,0))*D23/100,"?"))
E24: =IF(OR(C24="",D24=""),"",IFERROR(INDEX('Qida bazası'!$D$2:$D$103,MATCH(C24,'Qida bazası'!$A$2:$A$103,0))*D24/100,"?")) | F24: =IF(OR(C24="",D24=""),"",IFERROR(INDEX('Qida bazası'!$E$2:$E$103,MATCH(C24,'Qida bazası'!$A$2:$A$103,0))*D24/100,"?")) | G24: =IF(OR(C24="",D24=""),"",IFERROR(INDEX('Qida bazası'!$F$2:$F$103,MATCH(C24,'Qida bazası'!$A$2:$A$103,0))*D24/100,"?")) | H24: =IF(OR(C24="",D24=""),"",IFERROR(INDEX('Qida bazası'!$G$2:$G$103,MATCH(C24,'Qida bazası'!$A$2:$A$103,0))*D24/100,"?"))
E25: =IF(OR(C25="",D25=""),"",IFERROR(INDEX('Qida bazası'!$D$2:$D$103,MATCH(C25,'Qida bazası'!$A$2:$A$103,0))*D25/100,"?")) | F25: =IF(OR(C25="",D25=""),"",IFERROR(INDEX('Qida bazası'!$E$2:$E$103,MATCH(C25,'Qida bazası'!$A$2:$A$103,0))*D25/100,"?")) | G25: =IF(OR(C25="",D25=""),"",IFERROR(INDEX('Qida bazası'!$F$2:$F$103,MATCH(C25,'Qida bazası'!$A$2:$A$103,0))*D25/100,"?")) | H25: =IF(OR(C25="",D25=""),"",IFERROR(INDEX('Qida bazası'!$G$2:$G$103,MATCH(C25,'Qida bazası'!$A$2:$A$103,0))*D25/100,"?"))
E26: =IF(OR(C26="",D26=""),"",IFERROR(INDEX('Qida bazası'!$D$2:$D$103,MATCH(C26,'Qida bazası'!$A$2:$A$103,0))*D26/100,"?")) | F26: =IF(OR(C26="",D26=""),"",IFERROR(INDEX('Qida bazası'!$E$2:$E$103,MATCH(C26,'Qida bazası'!$A$2:$A$103,0))*D26/100,"?")) | G26: =IF(OR(C26="",D26=""),"",IFERROR(INDEX('Qida bazası'!$F$2:$F$103,MATCH(C26,'Qida bazası'!$A$2:$A$103,0))*D26/100,"?")) | H26: =IF(OR(C26="",D26=""),"",IFERROR(INDEX('Qida bazası'!$G$2:$G$103,MATCH(C26,'Qida bazası'!$A$2:$A$103,0))*D26/100,"?"))
E27: =IF(OR(C27="",D27=""),"",IFERROR(INDEX('Qida bazası'!$D$2:$D$103,MATCH(C27,'Qida bazası'!$A$2:$A$103,0))*D27/100,"?")) | F27: =IF(OR(C27="",D27=""),"",IFERROR(INDEX('Qida bazası'!$E$2:$E$103,MATCH(C27,'Qida bazası'!$A$2:$A$103,0))*D27/100,"?")) | G27: =IF(OR(C27="",D27=""),"",IFERROR(INDEX('Qida bazası'!$F$2:$F$103,MATCH(C27,'Qida bazası'!$A$2:$A$103,0))*D27/100,"?")) | H27: =IF(OR(C27="",D27=""),"",IFERROR(INDEX('Qida bazası'!$G$2:$G$103,MATCH(C27,'Qida bazası'!$A$2:$A$103,0))*D27/100,"?"))
E28: =IF(OR(C28="",D28=""),"",IFERROR(INDEX('Qida bazası'!$D$2:$D$103,MATCH(C28,'Qida bazası'!$A$2:$A$103,0))*D28/100,"?")) | F28: =IF(OR(C28="",D28=""),"",IFERROR(INDEX('Qida bazası'!$E$2:$E$103,MATCH(C28,'Qida bazası'!$A$2:$A$103,0))*D28/100,"?")) | G28: =IF(OR(C28="",D28=""),"",IFERROR(INDEX('Qida bazası'!$F$2:$F$103,MATCH(C28,'Qida bazası'!$A$2:$A$103,0))*D28/100,"?")) | H28: =IF(OR(C28="",D28=""),"",IFERROR(INDEX('Qida bazası'!$G$2:$G$103,MATCH(C28,'Qida bazası'!$A$2:$A$103,0))*D28/100,"?"))
E29: =IF(OR(C29="",D29=""),"",IFERROR(INDEX('Qida bazası'!$D$2:$D$103,MATCH(C29,'Qida bazası'!$A$2:$A$103,0))*D29/100,"?")) | F29: =IF(OR(C29="",D29=""),"",IFERROR(INDEX('Qida bazası'!$E$2:$E$103,MATCH(C29,'Qida bazası'!$A$2:$A$103,0))*D29/100,"?")) | G29: =IF(OR(C29="",D29=""),"",IFERROR(INDEX('Qida bazası'!$F$2:$F$103,MATCH(C29,'Qida bazası'!$A$2:$A$103,0))*D29/100,"?")) | H29: =IF(OR(C29="",D29=""),"",IFERROR(INDEX('Qida bazası'!$G$2:$G$103,MATCH(C29,'Qida bazası'!$A$2:$A$103,0))*D29/100,"?"))
E30: =IF(OR(C30="",D30=""),"",IFERROR(INDEX('Qida bazası'!$D$2:$D$103,MATCH(C30,'Qida bazası'!$A$2:$A$103,0))*D30/100,"?")) | F30: =IF(OR(C30="",D30=""),"",IFERROR(INDEX('Qida bazası'!$E$2:$E$103,MATCH(C30,'Qida bazası'!$A$2:$A$103,0))*D30/100,"?")) | G30: =IF(OR(C30="",D30=""),"",IFERROR(INDEX('Qida bazası'!$F$2:$F$103,MATCH(C30,'Qida bazası'!$A$2:$A$103,0))*D30/100,"?")) | H30: =IF(OR(C30="",D30=""),"",IFERROR(INDEX('Qida bazası'!$G$2:$G$103,MATCH(C30,'Qida bazası'!$A$2:$A$103,0))*D30/100,"?"))
E31: =IF(OR(C31="",D31=""),"",IFERROR(INDEX('Qida bazası'!$D$2:$D$103,MATCH(C31,'Qida bazası'!$A$2:$A$103,0))*D31/100,"?")) | F31: =IF(OR(C31="",D31=""),"",IFERROR(INDEX('Qida bazası'!$E$2:$E$103,MATCH(C31,'Qida bazası'!$A$2:$A$103,0))*D31/100,"?")) | G31: =IF(OR(C31="",D31=""),"",IFERROR(INDEX('Qida bazası'!$F$2:$F$103,MATCH(C31,'Qida bazası'!$A$2:$A$103,0))*D31/100,"?")) | H31: =IF(OR(C31="",D31=""),"",IFERROR(INDEX('Qida bazası'!$G$2:$G$103,MATCH(C31,'Qida bazası'!$A$2:$A$103,0))*D31/100,"?"))
... E2001: =IF(OR(C2001="",D2001=""),"",IFERROR(INDEX('Qida bazası'!$D$2:$D$103,MATCH(C2001,'Qida bazası'!$A$2:$A$103,0))*D2001/100,"?")) | F2001: =IF(OR(C2001="",D2001=""),"",IFERROR(INDEX('Qida bazası'!$E$2:$E$103,MATCH(C2001,'Qida bazası'!$A$2:$A$103,0))*D2001/100,"?")) | G2001: =IF(OR(C2001="",D2001=""),"",IFERROR(INDEX('Qida bazası'!$F$2:$F$103,MATCH(C2001,'Qida bazası'!$A$2:$A$103,0))*D2001/100,"?")) | H2001: =IF(OR(C2001="",D2001=""),"",IFERROR(INDEX('Qida bazası'!$G$2:$G$103,MATCH(C2001,'Qida bazası'!$A$2:$A$103,0))*D2001/100,"?"))

Sheet Günlər
A1: Tarix | B1: Gün | C1: Tip | D1: Tennis, dəq | E1: Tennis növü | F1: Norma kkal | G1: Yeyilən kkal | H1: Fərq | I1: Status | J1: Protein | K1: Protein min | L1: Karb. | M1: Yağ | N1: Çəki, kq | O1: 7 gün orta çəki
A2: 46304 | B2: Cümə | C2: Zal | E2: Tək | F2: =ROUND(((10*Profil!$B$4+6.25*Profil!$B$5-5*Profil!$B$6+5)*Profil!$B$7+Profil!$B$8+IF(C2="Zal",Profil!$B$9,0)+IF(N(D2)>0,IF(E2="Cüt",5,7)*Profil!$B$4*D2/60,0))/10,0)*10 | G2: =IF(COUNTIF(Gündəlik!$A$2:$A$2001,A2)=0,"",SUMIFS(Gündəlik!$E$2:$E$2001,Gündəlik!$A$2:$A$2001,A2)) | H2: =IF(G2="","",G2-F2) | I2: =IF(G2="","",IF(G2<F2*0.9,"az",IF(G2>F2*1.15,"çox","normada"))) | J2: =IF(G2="","",SUMIFS(Gündəlik!$F$2:$F$2001,Gündəlik!$A$2:$A$2001,A2)) | K2: =ROUND(Profil!$B$10*Profil!$B$4,0) | L2: =IF(G2="","",SUMIFS(Gündəlik!$G$2:$G$2001,Gündəlik!$A$2:$A$2001,A2)) | M2: =IF(G2="","",SUMIFS(Gündəlik!$H$2:$H$2001,Gündəlik!$A$2:$A$2001,A2)) | O2: =IF(COUNTIFS($A$2:$A$121,">="&(A2-6),$A$2:$A$121,"<="&A2,$N$2:$N$121,">0")<3,"",AVERAGEIFS($N$2:$N$121,$A$2:$A$121,">="&(A2-6),$A$2:$A$121,"<="&A2,$N$2:$N$121,">0"))
A3: 46305 | B3: Şənbə | C3: İstirahət | E3: Tək | F3: =ROUND(((10*Profil!$B$4+6.25*Profil!$B$5-5*Profil!$B$6+5)*Profil!$B$7+Profil!$B$8+IF(C3="Zal",Profil!$B$9,0)+IF(N(D3)>0,IF(E3="Cüt",5,7)*Profil!$B$4*D3/60,0))/10,0)*10 | G3: =IF(COUNTIF(Gündəlik!$A$2:$A$2001,A3)=0,"",SUMIFS(Gündəlik!$E$2:$E$2001,Gündəlik!$A$2:$A$2001,A3)) | H3: =IF(G3="","",G3-F3) | I3: =IF(G3="","",IF(G3<F3*0.9,"az",IF(G3>F3*1.15,"çox","normada"))) | J3: =IF(G3="","",SUMIFS(Gündəlik!$F$2:$F$2001,Gündəlik!$A$2:$A$2001,A3)) | K3: =ROUND(Profil!$B$10*Profil!$B$4,0) | L3: =IF(G3="","",SUMIFS(Gündəlik!$G$2:$G$2001,Gündəlik!$A$2:$A$2001,A3)) | M3: =IF(G3="","",SUMIFS(Gündəlik!$H$2:$H$2001,Gündəlik!$A$2:$A$2001,A3)) | O3: =IF(COUNTIFS($A$2:$A$121,">="&(A3-6),$A$2:$A$121,"<="&A3,$N$2:$N$121,">0")<3,"",AVERAGEIFS($N$2:$N$121,$A$2:$A$121,">="&(A3-6),$A$2:$A$121,"<="&A3,$N$2:$N$121,">0"))
A4: 46306 | B4: Bazar | C4: İstirahət | E4: Tək | F4: =ROUND(((10*Profil!$B$4+6.25*Profil!$B$5-5*Profil!$B$6+5)*Profil!$B$7+Profil!$B$8+IF(C4="Zal",Profil!$B$9,0)+IF(N(D4)>0,IF(E4="Cüt",5,7)*Profil!$B$4*D4/60,0))/10,0)*10 | G4: =IF(COUNTIF(Gündəlik!$A$2:$A$2001,A4)=0,"",SUMIFS(Gündəlik!$E$2:$E$2001,Gündəlik!$A$2:$A$2001,A4)) | H4: =IF(G4="","",G4-F4) | I4: =IF(G4="","",IF(G4<F4*0.9,"az",IF(G4>F4*1.15,"çox","normada"))) | J4: =IF(G4="","",SUMIFS(Gündəlik!$F$2:$F$2001,Gündəlik!$A$2:$A$2001,A4)) | K4: =ROUND(Profil!$B$10*Profil!$B$4,0) | L4: =IF(G4="","",SUMIFS(Gündəlik!$G$2:$G$2001,Gündəlik!$A$2:$A$2001,A4)) | M4: =IF(G4="","",SUMIFS(Gündəlik!$H$2:$H$2001,Gündəlik!$A$2:$A$2001,A4)) | O4: =IF(COUNTIFS($A$2:$A$121,">="&(A4-6),$A$2:$A$121,"<="&A4,$N$2:$N$121,">0")<3,"",AVERAGEIFS($N$2:$N$121,$A$2:$A$121,">="&(A4-6),$A$2:$A$121,"<="&A4,$N$2:$N$121,">0"))
A5: 46307 | B5: Bazar ertəsi | C5: Zal | E5: Tək | F5: =ROUND(((10*Profil!$B$4+6.25*Profil!$B$5-5*Profil!$B$6+5)*Profil!$B$7+Profil!$B$8+IF(C5="Zal",Profil!$B$9,0)+IF(N(D5)>0,IF(E5="Cüt",5,7)*Profil!$B$4*D5/60,0))/10,0)*10 | G5: =IF(COUNTIF(Gündəlik!$A$2:$A$2001,A5)=0,"",SUMIFS(Gündəlik!$E$2:$E$2001,Gündəlik!$A$2:$A$2001,A5)) | H5: =IF(G5="","",G5-F5) | I5: =IF(G5="","",IF(G5<F5*0.9,"az",IF(G5>F5*1.15,"çox","normada"))) | J5: =IF(G5="","",SUMIFS(Gündəlik!$F$2:$F$2001,Gündəlik!$A$2:$A$2001,A5)) | K5: =ROUND(Profil!$B$10*Profil!$B$4,0) | L5: =IF(G5="","",SUMIFS(Gündəlik!$G$2:$G$2001,Gündəlik!$A$2:$A$2001,A5)) | M5: =IF(G5="","",SUMIFS(Gündəlik!$H$2:$H$2001,Gündəlik!$A$2:$A$2001,A5)) | O5: =IF(COUNTIFS($A$2:$A$121,">="&(A5-6),$A$2:$A$121,"<="&A5,$N$2:$N$121,">0")<3,"",AVERAGEIFS($N$2:$N$121,$A$2:$A$121,">="&(A5-6),$A$2:$A$121,"<="&A5,$N$2:$N$121,">0"))
A6: 46308 | B6: Çərşənbə axşamı | C6: İstirahət | E6: Tək | F6: =ROUND(((10*Profil!$B$4+6.25*Profil!$B$5-5*Profil!$B$6+5)*Profil!$B$7+Profil!$B$8+IF(C6="Zal",Profil!$B$9,0)+IF(N(D6)>0,IF(E6="Cüt",5,7)*Profil!$B$4*D6/60,0))/10,0)*10 | G6: =IF(COUNTIF(Gündəlik!$A$2:$A$2001,A6)=0,"",SUMIFS(Gündəlik!$E$2:$E$2001,Gündəlik!$A$2:$A$2001,A6)) | H6: =IF(G6="","",G6-F6) | I6: =IF(G6="","",IF(G6<F6*0.9,"az",IF(G6>F6*1.15,"çox","normada"))) | J6: =IF(G6="","",SUMIFS(Gündəlik!$F$2:$F$2001,Gündəlik!$A$2:$A$2001,A6)) | K6: =ROUND(Profil!$B$10*Profil!$B$4,0) | L6: =IF(G6="","",SUMIFS(Gündəlik!$G$2:$G$2001,Gündəlik!$A$2:$A$2001,A6)) | M6: =IF(G6="","",SUMIFS(Gündəlik!$H$2:$H$2001,Gündəlik!$A$2:$A$2001,A6)) | O6: =IF(COUNTIFS($A$2:$A$121,">="&(A6-6),$A$2:$A$121,"<="&A6,$N$2:$N$121,">0")<3,"",AVERAGEIFS($N$2:$N$121,$A$2:$A$121,">="&(A6-6),$A$2:$A$121,"<="&A6,$N$2:$N$121,">0"))
A7: 46309 | B7: Çərşənbə | C7: Zal | E7: Tək | F7: =ROUND(((10*Profil!$B$4+6.25*Profil!$B$5-5*Profil!$B$6+5)*Profil!$B$7+Profil!$B$8+IF(C7="Zal",Profil!$B$9,0)+IF(N(D7)>0,IF(E7="Cüt",5,7)*Profil!$B$4*D7/60,0))/10,0)*10 | G7: =IF(COUNTIF(Gündəlik!$A$2:$A$2001,A7)=0,"",SUMIFS(Gündəlik!$E$2:$E$2001,Gündəlik!$A$2:$A$2001,A7)) | H7: =IF(G7="","",G7-F7) | I7: =IF(G7="","",IF(G7<F7*0.9,"az",IF(G7>F7*1.15,"çox","normada"))) | J7: =IF(G7="","",SUMIFS(Gündəlik!$F$2:$F$2001,Gündəlik!$A$2:$A$2001,A7)) | K7: =ROUND(Profil!$B$10*Profil!$B$4,0) | L7: =IF(G7="","",SUMIFS(Gündəlik!$G$2:$G$2001,Gündəlik!$A$2:$A$2001,A7)) | M7: =IF(G7="","",SUMIFS(Gündəlik!$H$2:$H$2001,Gündəlik!$A$2:$A$2001,A7)) | O7: =IF(COUNTIFS($A$2:$A$121,">="&(A7-6),$A$2:$A$121,"<="&A7,$N$2:$N$121,">0")<3,"",AVERAGEIFS($N$2:$N$121,$A$2:$A$121,">="&(A7-6),$A$2:$A$121,"<="&A7,$N$2:$N$121,">0"))
A8: 46310 | B8: Cümə axşamı | C8: İstirahət | E8: Tək | F8: =ROUND(((10*Profil!$B$4+6.25*Profil!$B$5-5*Profil!$B$6+5)*Profil!$B$7+Profil!$B$8+IF(C8="Zal",Profil!$B$9,0)+IF(N(D8)>0,IF(E8="Cüt",5,7)*Profil!$B$4*D8/60,0))/10,0)*10 | G8: =IF(COUNTIF(Gündəlik!$A$2:$A$2001,A8)=0,"",SUMIFS(Gündəlik!$E$2:$E$2001,Gündəlik!$A$2:$A$2001,A8)) | H8: =IF(G8="","",G8-F8) | I8: =IF(G8="","",IF(G8<F8*0.9,"az",IF(G8>F8*1.15,"çox","normada"))) | J8: =IF(G8="","",SUMIFS(Gündəlik!$F$2:$F$2001,Gündəlik!$A$2:$A$2001,A8)) | K8: =ROUND(Profil!$B$10*Profil!$B$4,0) | L8: =IF(G8="","",SUMIFS(Gündəlik!$G$2:$G$2001,Gündəlik!$A$2:$A$2001,A8)) | M8: =IF(G8="","",SUMIFS(Gündəlik!$H$2:$H$2001,Gündəlik!$A$2:$A$2001,A8)) | O8: =IF(COUNTIFS($A$2:$A$121,">="&(A8-6),$A$2:$A$121,"<="&A8,$N$2:$N$121,">0")<3,"",AVERAGEIFS($N$2:$N$121,$A$2:$A$121,">="&(A8-6),$A$2:$A$121,"<="&A8,$N$2:$N$121,">0"))
A9: 46311 | B9: Cümə | C9: Zal | E9: Tək | F9: =ROUND(((10*Profil!$B$4+6.25*Profil!$B$5-5*Profil!$B$6+5)*Profil!$B$7+Profil!$B$8+IF(C9="Zal",Profil!$B$9,0)+IF(N(D9)>0,IF(E9="Cüt",5,7)*Profil!$B$4*D9/60,0))/10,0)*10 | G9: =IF(COUNTIF(Gündəlik!$A$2:$A$2001,A9)=0,"",SUMIFS(Gündəlik!$E$2:$E$2001,Gündəlik!$A$2:$A$2001,A9)) | H9: =IF(G9="","",G9-F9) | I9: =IF(G9="","",IF(G9<F9*0.9,"az",IF(G9>F9*1.15,"çox","normada"))) | J9: =IF(G9="","",SUMIFS(Gündəlik!$F$2:$F$2001,Gündəlik!$A$2:$A$2001,A9)) | K9: =ROUND(Profil!$B$10*Profil!$B$4,0) | L9: =IF(G9="","",SUMIFS(Gündəlik!$G$2:$G$2001,Gündəlik!$A$2:$A$2001,A9)) | M9: =IF(G9="","",SUMIFS(Gündəlik!$H$2:$H$2001,Gündəlik!$A$2:$A$2001,A9)) | O9: =IF(COUNTIFS($A$2:$A$121,">="&(A9-6),$A$2:$A$121,"<="&A9,$N$2:$N$121,">0")<3,"",AVERAGEIFS($N$2:$N$121,$A$2:$A$121,">="&(A9-6),$A$2:$A$121,"<="&A9,$N$2:$N$121,">0"))
A10: 46312 | B10: Şənbə | C10: İstirahət | E10: Tək | F10: =ROUND(((10*Profil!$B$4+6.25*Profil!$B$5-5*Profil!$B$6+5)*Profil!$B$7+Profil!$B$8+IF(C10="Zal",Profil!$B$9,0)+IF(N(D10)>0,IF(E10="Cüt",5,7)*Profil!$B$4*D10/60,0))/10,0)*10 | G10: =IF(COUNTIF(Gündəlik!$A$2:$A$2001,A10)=0,"",SUMIFS(Gündəlik!$E$2:$E$2001,Gündəlik!$A$2:$A$2001,A10)) | H10: =IF(G10="","",G10-F10) | I10: =IF(G10="","",IF(G10<F10*0.9,"az",IF(G10>F10*1.15,"çox","normada"))) | J10: =IF(G10="","",SUMIFS(Gündəlik!$F$2:$F$2001,Gündəlik!$A$2:$A$2001,A10)) | K10: =ROUND(Profil!$B$10*Profil!$B$4,0) | L10: =IF(G10="","",SUMIFS(Gündəlik!$G$2:$G$2001,Gündəlik!$A$2:$A$2001,A10)) | M10: =IF(G10="","",SUMIFS(Gündəlik!$H$2:$H$2001,Gündəlik!$A$2:$A$2001,A10)) | O10: =IF(COUNTIFS($A$2:$A$121,">="&(A10-6),$A$2:$A$121,"<="&A10,$N$2:$N$121,">0")<3,"",AVERAGEIFS($N$2:$N$121,$A$2:$A$121,">="&(A10-6),$A$2:$A$121,"<="&A10,$N$2:$N$121,">0"))
A11: 46313 | B11: Bazar | C11: İstirahət | E11: Tək | F11: =ROUND(((10*Profil!$B$4+6.25*Profil!$B$5-5*Profil!$B$6+5)*Profil!$B$7+Profil!$B$8+IF(C11="Zal",Profil!$B$9,0)+IF(N(D11)>0,IF(E11="Cüt",5,7)*Profil!$B$4*D11/60,0))/10,0)*10 | G11: =IF(COUNTIF(Gündəlik!$A$2:$A$2001,A11)=0,"",SUMIFS(Gündəlik!$E$2:$E$2001,Gündəlik!$A$2:$A$2001,A11)) | H11: =IF(G11="","",G11-F11) | I11: =IF(G11="","",IF(G11<F11*0.9,"az",IF(G11>F11*1.15,"çox","normada"))) | J11: =IF(G11="","",SUMIFS(Gündəlik!$F$2:$F$2001,Gündəlik!$A$2:$A$2001,A11)) | K11: =ROUND(Profil!$B$10*Profil!$B$4,0) | L11: =IF(G11="","",SUMIFS(Gündəlik!$G$2:$G$2001,Gündəlik!$A$2:$A$2001,A11)) | M11: =IF(G11="","",SUMIFS(Gündəlik!$H$2:$H$2001,Gündəlik!$A$2:$A$2001,A11)) | O11: =IF(COUNTIFS($A$2:$A$121,">="&(A11-6),$A$2:$A$121,"<="&A11,$N$2:$N$121,">0")<3,"",AVERAGEIFS($N$2:$N$121,$A$2:$A$121,">="&(A11-6),$A$2:$A$121,"<="&A11,$N$2:$N$121,">0"))
A12: 46314 | B12: Bazar ertəsi | C12: Zal | E12: Tək | F12: =ROUND(((10*Profil!$B$4+6.25*Profil!$B$5-5*Profil!$B$6+5)*Profil!$B$7+Profil!$B$8+IF(C12="Zal",Profil!$B$9,0)+IF(N(D12)>0,IF(E12="Cüt",5,7)*Profil!$B$4*D12/60,0))/10,0)*10 | G12: =IF(COUNTIF(Gündəlik!$A$2:$A$2001,A12)=0,"",SUMIFS(Gündəlik!$E$2:$E$2001,Gündəlik!$A$2:$A$2001,A12)) | H12: =IF(G12="","",G12-F12) | I12: =IF(G12="","",IF(G12<F12*0.9,"az",IF(G12>F12*1.15,"çox","normada"))) | J12: =IF(G12="","",SUMIFS(Gündəlik!$F$2:$F$2001,Gündəlik!$A$2:$A$2001,A12)) | K12: =ROUND(Profil!$B$10*Profil!$B$4,0) | L12: =IF(G12="","",SUMIFS(Gündəlik!$G$2:$G$2001,Gündəlik!$A$2:$A$2001,A12)) | M12: =IF(G12="","",SUMIFS(Gündəlik!$H$2:$H$2001,Gündəlik!$A$2:$A$2001,A12)) | O12: =IF(COUNTIFS($A$2:$A$121,">="&(A12-6),$A$2:$A$121,"<="&A12,$N$2:$N$121,">0")<3,"",AVERAGEIFS($N$2:$N$121,$A$2:$A$121,">="&(A12-6),$A$2:$A$121,"<="&A12,$N$2:$N$121,">0"))
A13: 46315 | B13: Çərşənbə axşamı | C13: İstirahət | E13: Tək | F13: =ROUND(((10*Profil!$B$4+6.25*Profil!$B$5-5*Profil!$B$6+5)*Profil!$B$7+Profil!$B$8+IF(C13="Zal",Profil!$B$9,0)+IF(N(D13)>0,IF(E13="Cüt",5,7)*Profil!$B$4*D13/60,0))/10,0)*10 | G13: =IF(COUNTIF(Gündəlik!$A$2:$A$2001,A13)=0,"",SUMIFS(Gündəlik!$E$2:$E$2001,Gündəlik!$A$2:$A$2001,A13)) | H13: =IF(G13="","",G13-F13) | I13: =IF(G13="","",IF(G13<F13*0.9,"az",IF(G13>F13*1.15,"çox","normada"))) | J13: =IF(G13="","",SUMIFS(Gündəlik!$F$2:$F$2001,Gündəlik!$A$2:$A$2001,A13)) | K13: =ROUND(Profil!$B$10*Profil!$B$4,0) | L13: =IF(G13="","",SUMIFS(Gündəlik!$G$2:$G$2001,Gündəlik!$A$2:$A$2001,A13)) | M13: =IF(G13="","",SUMIFS(Gündəlik!$H$2:$H$2001,Gündəlik!$A$2:$A$2001,A13)) | O13: =IF(COUNTIFS($A$2:$A$121,">="&(A13-6),$A$2:$A$121,"<="&A13,$N$2:$N$121,">0")<3,"",AVERAGEIFS($N$2:$N$121,$A$2:$A$121,">="&(A13-6),$A$2:$A$121,"<="&A13,$N$2:$N$121,">0"))
... A121: 46423 | B121: Cümə | C121: Zal | E121: Tək | F121: =ROUND(((10*Profil!$B$4+6.25*Profil!$B$5-5*Profil!$B$6+5)*Profil!$B$7+Profil!$B$8+IF(C121="Zal",Profil!$B$9,0)+IF(N(D121)>0,IF(E121="Cüt",5,7)*Profil!$B$4*D121/60,0))/10,0)*10 | G121: =IF(COUNTIF(Gündəlik!$A$2:$A$2001,A121)=0,"",SUMIFS(Gündəlik!$E$2:$E$2001,Gündəlik!$A$2:$A$2001,A121)) | H121: =IF(G121="","",G121-F121) | I121: =IF(G121="","",IF(G121<F121*0.9,"az",IF(G121>F121*1.15,"çox","normada"))) | J121: =IF(G121="","",SUMIFS(Gündəlik!$F$2:$F$2001,Gündəlik!$A$2:$A$2001,A121)) | K121: =ROUND(Profil!$B$10*Profil!$B$4,0) | L121: =IF(G121="","",SUMIFS(Gündəlik!$G$2:$G$2001,Gündəlik!$A$2:$A$2001,A121)) | M121: =IF(G121="","",SUMIFS(Gündəlik!$H$2:$H$2001,Gündəlik!$A$2:$A$2001,A121)) | O121: =IF(COUNTIFS($A$2:$A$121,">="&(A121-6),$A$2:$A$121,"<="&A121,$N$2:$N$121,">0")<3,"",AVERAGEIFS($N$2:$N$121,$A$2:$A$121,">="&(A121-6),$A$2:$A$121,"<="&A121,$N$2:$N$121,">0"))

Sheet Həftəlik
A1: Həftə (B.e.) | B1: Yazılmış gün | C1: Orta kkal | D1: Orta norma | E1: Orta protein | F1: Zal günləri | G1: Tennis, dəq | H1: Orta çəki | I1: Dəyişmə, kq | J1: Tövsiyə
A2: 46300 | B2: =COUNTIFS(Günlər!$A$2:$A$121,">="&A2,Günlər!$A$2:$A$121,"<"&(A2+7),Günlər!$G$2:$G$121,">0") | C2: =IF(B2=0,"",AVERAGEIFS(Günlər!$G$2:$G$121,Günlər!$A$2:$A$121,">="&A2,Günlər!$A$2:$A$121,"<"&(A2+7),Günlər!$G$2:$G$121,">0")) | D2: =IF(B2=0,"",AVERAGEIFS(Günlər!$F$2:$F$121,Günlər!$A$2:$A$121,">="&A2,Günlər!$A$2:$A$121,"<"&(A2+7),Günlər!$G$2:$G$121,">0")) | E2: =IF(B2=0,"",AVERAGEIFS(Günlər!$J$2:$J$121,Günlər!$A$2:$A$121,">="&A2,Günlər!$A$2:$A$121,"<"&(A2+7),Günlər!$G$2:$G$121,">0")) | F2: =COUNTIFS(Günlər!$A$2:$A$121,">="&A2,Günlər!$A$2:$A$121,"<"&(A2+7),Günlər!$C$2:$C$121,"Zal") | G2: =SUMIFS(Günlər!$D$2:$D$121,Günlər!$A$2:$A$121,">="&A2,Günlər!$A$2:$A$121,"<"&(A2+7)) | H2: =IF(COUNTIFS(Günlər!$A$2:$A$121,">="&A2,Günlər!$A$2:$A$121,"<"&(A2+7),Günlər!$N$2:$N$121,">0")<3,"",AVERAGEIFS(Günlər!$N$2:$N$121,Günlər!$A$2:$A$121,">="&A2,Günlər!$A$2:$A$121,"<"&(A2+7),Günlər!$N$2:$N$121,">0")) | J2: =IF(B2=0,"",IF(AND(I2<>"",I2<0.1),"Artım yavaşdır: Profil → artıq kaloriyə +150",IF(AND(I2<>"",I2>0.4),"Çox sürətli: Profil → artıq kaloridən −150",IF(C2<D2*0.9,"Az yeyirsən: hər gün +1 qəlyanaltı",IF(E2<Profil!$B$20*0.95,"Proteini artır","Əla, belə davam et")))))
A3: 46307 | B3: =COUNTIFS(Günlər!$A$2:$A$121,">="&A3,Günlər!$A$2:$A$121,"<"&(A3+7),Günlər!$G$2:$G$121,">0") | C3: =IF(B3=0,"",AVERAGEIFS(Günlər!$G$2:$G$121,Günlər!$A$2:$A$121,">="&A3,Günlər!$A$2:$A$121,"<"&(A3+7),Günlər!$G$2:$G$121,">0")) | D3: =IF(B3=0,"",AVERAGEIFS(Günlər!$F$2:$F$121,Günlər!$A$2:$A$121,">="&A3,Günlər!$A$2:$A$121,"<"&(A3+7),Günlər!$G$2:$G$121,">0")) | E3: =IF(B3=0,"",AVERAGEIFS(Günlər!$J$2:$J$121,Günlər!$A$2:$A$121,">="&A3,Günlər!$A$2:$A$121,"<"&(A3+7),Günlər!$G$2:$G$121,">0")) | F3: =COUNTIFS(Günlər!$A$2:$A$121,">="&A3,Günlər!$A$2:$A$121,"<"&(A3+7),Günlər!$C$2:$C$121,"Zal") | G3: =SUMIFS(Günlər!$D$2:$D$121,Günlər!$A$2:$A$121,">="&A3,Günlər!$A$2:$A$121,"<"&(A3+7)) | H3: =IF(COUNTIFS(Günlər!$A$2:$A$121,">="&A3,Günlər!$A$2:$A$121,"<"&(A3+7),Günlər!$N$2:$N$121,">0")<3,"",AVERAGEIFS(Günlər!$N$2:$N$121,Günlər!$A$2:$A$121,">="&A3,Günlər!$A$2:$A$121,"<"&(A3+7),Günlər!$N$2:$N$121,">0")) | I3: =IF(OR(H3="",H2=""),"",H3-H2) | J3: =IF(B3=0,"",IF(AND(I3<>"",I3<0.1),"Artım yavaşdır: Profil → artıq kaloriyə +150",IF(AND(I3<>"",I3>0.4),"Çox sürətli: Profil → artıq kaloridən −150",IF(C3<D3*0.9,"Az yeyirsən: hər gün +1 qəlyanaltı",IF(E3<Profil!$B$20*0.95,"Proteini artır","Əla, belə davam et")))))
A4: 46314 | B4: =COUNTIFS(Günlər!$A$2:$A$121,">="&A4,Günlər!$A$2:$A$121,"<"&(A4+7),Günlər!$G$2:$G$121,">0") | C4: =IF(B4=0,"",AVERAGEIFS(Günlər!$G$2:$G$121,Günlər!$A$2:$A$121,">="&A4,Günlər!$A$2:$A$121,"<"&(A4+7),Günlər!$G$2:$G$121,">0")) | D4: =IF(B4=0,"",AVERAGEIFS(Günlər!$F$2:$F$121,Günlər!$A$2:$A$121,">="&A4,Günlər!$A$2:$A$121,"<"&(A4+7),Günlər!$G$2:$G$121,">0")) | E4: =IF(B4=0,"",AVERAGEIFS(Günlər!$J$2:$J$121,Günlər!$A$2:$A$121,">="&A4,Günlər!$A$2:$A$121,"<"&(A4+7),Günlər!$G$2:$G$121,">0")) | F4: =COUNTIFS(Günlər!$A$2:$A$121,">="&A4,Günlər!$A$2:$A$121,"<"&(A4+7),Günlər!$C$2:$C$121,"Zal") | G4: =SUMIFS(Günlər!$D$2:$D$121,Günlər!$A$2:$A$121,">="&A4,Günlər!$A$2:$A$121,"<"&(A4+7)) | H4: =IF(COUNTIFS(Günlər!$A$2:$A$121,">="&A4,Günlər!$A$2:$A$121,"<"&(A4+7),Günlər!$N$2:$N$121,">0")<3,"",AVERAGEIFS(Günlər!$N$2:$N$121,Günlər!$A$2:$A$121,">="&A4,Günlər!$A$2:$A$121,"<"&(A4+7),Günlər!$N$2:$N$121,">0")) | I4: =IF(OR(H4="",H3=""),"",H4-H3) | J4: =IF(B4=0,"",IF(AND(I4<>"",I4<0.1),"Artım yavaşdır: Profil → artıq kaloriyə +150",IF(AND(I4<>"",I4>0.4),"Çox sürətli: Profil → artıq kaloridən −150",IF(C4<D4*0.9,"Az yeyirsən: hər gün +1 qəlyanaltı",IF(E4<Profil!$B$20*0.95,"Proteini artır","Əla, belə davam et")))))
A5: 46321 | B5: =COUNTIFS(Günlər!$A$2:$A$121,">="&A5,Günlər!$A$2:$A$121,"<"&(A5+7),Günlər!$G$2:$G$121,">0") | C5: =IF(B5=0,"",AVERAGEIFS(Günlər!$G$2:$G$121,Günlər!$A$2:$A$121,">="&A5,Günlər!$A$2:$A$121,"<"&(A5+7),Günlər!$G$2:$G$121,">0")) | D5: =IF(B5=0,"",AVERAGEIFS(Günlər!$F$2:$F$121,Günlər!$A$2:$A$121,">="&A5,Günlər!$A$2:$A$121,"<"&(A5+7),Günlər!$G$2:$G$121,">0")) | E5: =IF(B5=0,"",AVERAGEIFS(Günlər!$J$2:$J$121,Günlər!$A$2:$A$121,">="&A5,Günlər!$A$2:$A$121,"<"&(A5+7),Günlər!$G$2:$G$121,">0")) | F5: =COUNTIFS(Günlər!$A$2:$A$121,">="&A5,Günlər!$A$2:$A$121,"<"&(A5+7),Günlər!$C$2:$C$121,"Zal") | G5: =SUMIFS(Günlər!$D$2:$D$121,Günlər!$A$2:$A$121,">="&A5,Günlər!$A$2:$A$121,"<"&(A5+7)) | H5: =IF(COUNTIFS(Günlər!$A$2:$A$121,">="&A5,Günlər!$A$2:$A$121,"<"&(A5+7),Günlər!$N$2:$N$121,">0")<3,"",AVERAGEIFS(Günlər!$N$2:$N$121,Günlər!$A$2:$A$121,">="&A5,Günlər!$A$2:$A$121,"<"&(A5+7),Günlər!$N$2:$N$121,">0")) | I5: =IF(OR(H5="",H4=""),"",H5-H4) | J5: =IF(B5=0,"",IF(AND(I5<>"",I5<0.1),"Artım yavaşdır: Profil → artıq kaloriyə +150",IF(AND(I5<>"",I5>0.4),"Çox sürətli: Profil → artıq kaloridən −150",IF(C5<D5*0.9,"Az yeyirsən: hər gün +1 qəlyanaltı",IF(E5<Profil!$B$20*0.95,"Proteini artır","Əla, belə davam et")))))
A6: 46328 | B6: =COUNTIFS(Günlər!$A$2:$A$121,">="&A6,Günlər!$A$2:$A$121,"<"&(A6+7),Günlər!$G$2:$G$121,">0") | C6: =IF(B6=0,"",AVERAGEIFS(Günlər!$G$2:$G$121,Günlər!$A$2:$A$121,">="&A6,Günlər!$A$2:$A$121,"<"&(A6+7),Günlər!$G$2:$G$121,">0")) | D6: =IF(B6=0,"",AVERAGEIFS(Günlər!$F$2:$F$121,Günlər!$A$2:$A$121,">="&A6,Günlər!$A$2:$A$121,"<"&(A6+7),Günlər!$G$2:$G$121,">0")) | E6: =IF(B6=0,"",AVERAGEIFS(Günlər!$J$2:$J$121,Günlər!$A$2:$A$121,">="&A6,Günlər!$A$2:$A$121,"<"&(A6+7),Günlər!$G$2:$G$121,">0")) | F6: =COUNTIFS(Günlər!$A$2:$A$121,">="&A6,Günlər!$A$2:$A$121,"<"&(A6+7),Günlər!$C$2:$C$121,"Zal") | G6: =SUMIFS(Günlər!$D$2:$D$121,Günlər!$A$2:$A$121,">="&A6,Günlər!$A$2:$A$121,"<"&(A6+7)) | H6: =IF(COUNTIFS(Günlər!$A$2:$A$121,">="&A6,Günlər!$A$2:$A$121,"<"&(A6+7),Günlər!$N$2:$N$121,">0")<3,"",AVERAGEIFS(Günlər!$N$2:$N$121,Günlər!$A$2:$A$121,">="&A6,Günlər!$A$2:$A$121,"<"&(A6+7),Günlər!$N$2:$N$121,">0")) | I6: =IF(OR(H6="",H5=""),"",H6-H5) | J6: =IF(B6=0,"",IF(AND(I6<>"",I6<0.1),"Artım yavaşdır: Profil → artıq kaloriyə +150",IF(AND(I6<>"",I6>0.4),"Çox sürətli: Profil → artıq kaloridən −150",IF(C6<D6*0.9,"Az yeyirsən: hər gün +1 qəlyanaltı",IF(E6<Profil!$B$20*0.95,"Proteini artır","Əla, belə davam et")))))
A7: 46335 | B7: =COUNTIFS(Günlər!$A$2:$A$121,">="&A7,Günlər!$A$2:$A$121,"<"&(A7+7),Günlər!$G$2:$G$121,">0") | C7: =IF(B7=0,"",AVERAGEIFS(Günlər!$G$2:$G$121,Günlər!$A$2:$A$121,">="&A7,Günlər!$A$2:$A$121,"<"&(A7+7),Günlər!$G$2:$G$121,">0")) | D7: =IF(B7=0,"",AVERAGEIFS(Günlər!$F$2:$F$121,Günlər!$A$2:$A$121,">="&A7,Günlər!$A$2:$A$121,"<"&(A7+7),Günlər!$G$2:$G$121,">0")) | E7: =IF(B7=0,"",AVERAGEIFS(Günlər!$J$2:$J$121,Günlər!$A$2:$A$121,">="&A7,Günlər!$A$2:$A$121,"<"&(A7+7),Günlər!$G$2:$G$121,">0")) | F7: =COUNTIFS(Günlər!$A$2:$A$121,">="&A7,Günlər!$A$2:$A$121,"<"&(A7+7),Günlər!$C$2:$C$121,"Zal") | G7: =SUMIFS(Günlər!$D$2:$D$121,Günlər!$A$2:$A$121,">="&A7,Günlər!$A$2:$A$121,"<"&(A7+7)) | H7: =IF(COUNTIFS(Günlər!$A$2:$A$121,">="&A7,Günlər!$A$2:$A$121,"<"&(A7+7),Günlər!$N$2:$N$121,">0")<3,"",AVERAGEIFS(Günlər!$N$2:$N$121,Günlər!$A$2:$A$121,">="&A7,Günlər!$A$2:$A$121,"<"&(A7+7),Günlər!$N$2:$N$121,">0")) | I7: =IF(OR(H7="",H6=""),"",H7-H6) | J7: =IF(B7=0,"",IF(AND(I7<>"",I7<0.1),"Artım yavaşdır: Profil → artıq kaloriyə +150",IF(AND(I7<>"",I7>0.4),"Çox sürətli: Profil → artıq kaloridən −150",IF(C7<D7*0.9,"Az yeyirsən: hər gün +1 qəlyanaltı",IF(E7<Profil!$B$20*0.95,"Proteini artır","Əla, belə davam et")))))
A8: 46342 | B8: =COUNTIFS(Günlər!$A$2:$A$121,">="&A8,Günlər!$A$2:$A$121,"<"&(A8+7),Günlər!$G$2:$G$121,">0") | C8: =IF(B8=0,"",AVERAGEIFS(Günlər!$G$2:$G$121,Günlər!$A$2:$A$121,">="&A8,Günlər!$A$2:$A$121,"<"&(A8+7),Günlər!$G$2:$G$121,">0")) | D8: =IF(B8=0,"",AVERAGEIFS(Günlər!$F$2:$F$121,Günlər!$A$2:$A$121,">="&A8,Günlər!$A$2:$A$121,"<"&(A8+7),Günlər!$G$2:$G$121,">0")) | E8: =IF(B8=0,"",AVERAGEIFS(Günlər!$J$2:$J$121,Günlər!$A$2:$A$121,">="&A8,Günlər!$A$2:$A$121,"<"&(A8+7),Günlər!$G$2:$G$121,">0")) | F8: =COUNTIFS(Günlər!$A$2:$A$121,">="&A8,Günlər!$A$2:$A$121,"<"&(A8+7),Günlər!$C$2:$C$121,"Zal") | G8: =SUMIFS(Günlər!$D$2:$D$121,Günlər!$A$2:$A$121,">="&A8,Günlər!$A$2:$A$121,"<"&(A8+7)) | H8: =IF(COUNTIFS(Günlər!$A$2:$A$121,">="&A8,Günlər!$A$2:$A$121,"<"&(A8+7),Günlər!$N$2:$N$121,">0")<3,"",AVERAGEIFS(Günlər!$N$2:$N$121,Günlər!$A$2:$A$121,">="&A8,Günlər!$A$2:$A$121,"<"&(A8+7),Günlər!$N$2:$N$121,">0")) | I8: =IF(OR(H8="",H7=""),"",H8-H7) | J8: =IF(B8=0,"",IF(AND(I8<>"",I8<0.1),"Artım yavaşdır: Profil → artıq kaloriyə +150",IF(AND(I8<>"",I8>0.4),"Çox sürətli: Profil → artıq kaloridən −150",IF(C8<D8*0.9,"Az yeyirsən: hər gün +1 qəlyanaltı",IF(E8<Profil!$B$20*0.95,"Proteini artır","Əla, belə davam et")))))
A9: 46349 | B9: =COUNTIFS(Günlər!$A$2:$A$121,">="&A9,Günlər!$A$2:$A$121,"<"&(A9+7),Günlər!$G$2:$G$121,">0") | C9: =IF(B9=0,"",AVERAGEIFS(Günlər!$G$2:$G$121,Günlər!$A$2:$A$121,">="&A9,Günlər!$A$2:$A$121,"<"&(A9+7),Günlər!$G$2:$G$121,">0")) | D9: =IF(B9=0,"",AVERAGEIFS(Günlər!$F$2:$F$121,Günlər!$A$2:$A$121,">="&A9,Günlər!$A$2:$A$121,"<"&(A9+7),Günlər!$G$2:$G$121,">0")) | E9: =IF(B9=0,"",AVERAGEIFS(Günlər!$J$2:$J$121,Günlər!$A$2:$A$121,">="&A9,Günlər!$A$2:$A$121,"<"&(A9+7),Günlər!$G$2:$G$121,">0")) | F9: =COUNTIFS(Günlər!$A$2:$A$121,">="&A9,Günlər!$A$2:$A$121,"<"&(A9+7),Günlər!$C$2:$C$121,"Zal") | G9: =SUMIFS(Günlər!$D$2:$D$121,Günlər!$A$2:$A$121,">="&A9,Günlər!$A$2:$A$121,"<"&(A9+7)) | H9: =IF(COUNTIFS(Günlər!$A$2:$A$121,">="&A9,Günlər!$A$2:$A$121,"<"&(A9+7),Günlər!$N$2:$N$121,">0")<3,"",AVERAGEIFS(Günlər!$N$2:$N$121,Günlər!$A$2:$A$121,">="&A9,Günlər!$A$2:$A$121,"<"&(A9+7),Günlər!$N$2:$N$121,">0")) | I9: =IF(OR(H9="",H8=""),"",H9-H8) | J9: =IF(B9=0,"",IF(AND(I9<>"",I9<0.1),"Artım yavaşdır: Profil → artıq kaloriyə +150",IF(AND(I9<>"",I9>0.4),"Çox sürətli: Profil → artıq kaloridən −150",IF(C9<D9*0.9,"Az yeyirsən: hər gün +1 qəlyanaltı",IF(E9<Profil!$B$20*0.95,"Proteini artır","Əla, belə davam et")))))
A10: 46356 | B10: =COUNTIFS(Günlər!$A$2:$A$121,">="&A10,Günlər!$A$2:$A$121,"<"&(A10+7),Günlər!$G$2:$G$121,">0") | C10: =IF(B10=0,"",AVERAGEIFS(Günlər!$G$2:$G$121,Günlər!$A$2:$A$121,">="&A10,Günlər!$A$2:$A$121,"<"&(A10+7),Günlər!$G$2:$G$121,">0")) | D10: =IF(B10=0,"",AVERAGEIFS(Günlər!$F$2:$F$121,Günlər!$A$2:$A$121,">="&A10,Günlər!$A$2:$A$121,"<"&(A10+7),Günlər!$G$2:$G$121,">0")) | E10: =IF(B10=0,"",AVERAGEIFS(Günlər!$J$2:$J$121,Günlər!$A$2:$A$121,">="&A10,Günlər!$A$2:$A$121,"<"&(A10+7),Günlər!$G$2:$G$121,">0")) | F10: =COUNTIFS(Günlər!$A$2:$A$121,">="&A10,Günlər!$A$2:$A$121,"<"&(A10+7),Günlər!$C$2:$C$121,"Zal") | G10: =SUMIFS(Günlər!$D$2:$D$121,Günlər!$A$2:$A$121,">="&A10,Günlər!$A$2:$A$121,"<"&(A10+7)) | H10: =IF(COUNTIFS(Günlər!$A$2:$A$121,">="&A10,Günlər!$A$2:$A$121,"<"&(A10+7),Günlər!$N$2:$N$121,">0")<3,"",AVERAGEIFS(Günlər!$N$2:$N$121,Günlər!$A$2:$A$121,">="&A10,Günlər!$A$2:$A$121,"<"&(A10+7),Günlər!$N$2:$N$121,">0")) | I10: =IF(OR(H10="",H9=""),"",H10-H9) | J10: =IF(B10=0,"",IF(AND(I10<>"",I10<0.1),"Artım yavaşdır: Profil → artıq kaloriyə +150",IF(AND(I10<>"",I10>0.4),"Çox sürətli: Profil → artıq kaloridən −150",IF(C10<D10*0.9,"Az yeyirsən: hər gün +1 qəlyanaltı",IF(E10<Profil!$B$20*0.95,"Proteini artır","Əla, belə davam et")))))
A11: 46363 | B11: =COUNTIFS(Günlər!$A$2:$A$121,">="&A11,Günlər!$A$2:$A$121,"<"&(A11+7),Günlər!$G$2:$G$121,">0") | C11: =IF(B11=0,"",AVERAGEIFS(Günlər!$G$2:$G$121,Günlər!$A$2:$A$121,">="&A11,Günlər!$A$2:$A$121,"<"&(A11+7),Günlər!$G$2:$G$121,">0")) | D11: =IF(B11=0,"",AVERAGEIFS(Günlər!$F$2:$F$121,Günlər!$A$2:$A$121,">="&A11,Günlər!$A$2:$A$121,"<"&(A11+7),Günlər!$G$2:$G$121,">0")) | E11: =IF(B11=0,"",AVERAGEIFS(Günlər!$J$2:$J$121,Günlər!$A$2:$A$121,">="&A11,Günlər!$A$2:$A$121,"<"&(A11+7),Günlər!$G$2:$G$121,">0")) | F11: =COUNTIFS(Günlər!$A$2:$A$121,">="&A11,Günlər!$A$2:$A$121,"<"&(A11+7),Günlər!$C$2:$C$121,"Zal") | G11: =SUMIFS(Günlər!$D$2:$D$121,Günlər!$A$2:$A$121,">="&A11,Günlər!$A$2:$A$121,"<"&(A11+7)) | H11: =IF(COUNTIFS(Günlər!$A$2:$A$121,">="&A11,Günlər!$A$2:$A$121,"<"&(A11+7),Günlər!$N$2:$N$121,">0")<3,"",AVERAGEIFS(Günlər!$N$2:$N$121,Günlər!$A$2:$A$121,">="&A11,Günlər!$A$2:$A$121,"<"&(A11+7),Günlər!$N$2:$N$121,">0")) | I11: =IF(OR(H11="",H10=""),"",H11-H10) | J11: =IF(B11=0,"",IF(AND(I11<>"",I11<0.1),"Artım yavaşdır: Profil → artıq kaloriyə +150",IF(AND(I11<>"",I11>0.4),"Çox sürətli: Profil → artıq kaloridən −150",IF(C11<D11*0.9,"Az yeyirsən: hər gün +1 qəlyanaltı",IF(E11<Profil!$B$20*0.95,"Proteini artır","Əla, belə davam et")))))
A12: 46370 | B12: =COUNTIFS(Günlər!$A$2:$A$121,">="&A12,Günlər!$A$2:$A$121,"<"&(A12+7),Günlər!$G$2:$G$121,">0") | C12: =IF(B12=0,"",AVERAGEIFS(Günlər!$G$2:$G$121,Günlər!$A$2:$A$121,">="&A12,Günlər!$A$2:$A$121,"<"&(A12+7),Günlər!$G$2:$G$121,">0")) | D12: =IF(B12=0,"",AVERAGEIFS(Günlər!$F$2:$F$121,Günlər!$A$2:$A$121,">="&A12,Günlər!$A$2:$A$121,"<"&(A12+7),Günlər!$G$2:$G$121,">0")) | E12: =IF(B12=0,"",AVERAGEIFS(Günlər!$J$2:$J$121,Günlər!$A$2:$A$121,">="&A12,Günlər!$A$2:$A$121,"<"&(A12+7),Günlər!$G$2:$G$121,">0")) | F12: =COUNTIFS(Günlər!$A$2:$A$121,">="&A12,Günlər!$A$2:$A$121,"<"&(A12+7),Günlər!$C$2:$C$121,"Zal") | G12: =SUMIFS(Günlər!$D$2:$D$121,Günlər!$A$2:$A$121,">="&A12,Günlər!$A$2:$A$121,"<"&(A12+7)) | H12: =IF(COUNTIFS(Günlər!$A$2:$A$121,">="&A12,Günlər!$A$2:$A$121,"<"&(A12+7),Günlər!$N$2:$N$121,">0")<3,"",AVERAGEIFS(Günlər!$N$2:$N$121,Günlər!$A$2:$A$121,">="&A12,Günlər!$A$2:$A$121,"<"&(A12+7),Günlər!$N$2:$N$121,">0")) | I12: =IF(OR(H12="",H11=""),"",H12-H11) | J12: =IF(B12=0,"",IF(AND(I12<>"",I12<0.1),"Artım yavaşdır: Profil → artıq kaloriyə +150",IF(AND(I12<>"",I12>0.4),"Çox sürətli: Profil → artıq kaloridən −150",IF(C12<D12*0.9,"Az yeyirsən: hər gün +1 qəlyanaltı",IF(E12<Profil!$B$20*0.95,"Proteini artır","Əla, belə davam et")))))
A13: 46377 | B13: =COUNTIFS(Günlər!$A$2:$A$121,">="&A13,Günlər!$A$2:$A$121,"<"&(A13+7),Günlər!$G$2:$G$121,">0") | C13: =IF(B13=0,"",AVERAGEIFS(Günlər!$G$2:$G$121,Günlər!$A$2:$A$121,">="&A13,Günlər!$A$2:$A$121,"<"&(A13+7),Günlər!$G$2:$G$121,">0")) | D13: =IF(B13=0,"",AVERAGEIFS(Günlər!$F$2:$F$121,Günlər!$A$2:$A$121,">="&A13,Günlər!$A$2:$A$121,"<"&(A13+7),Günlər!$G$2:$G$121,">0")) | E13: =IF(B13=0,"",AVERAGEIFS(Günlər!$J$2:$J$121,Günlər!$A$2:$A$121,">="&A13,Günlər!$A$2:$A$121,"<"&(A13+7),Günlər!$G$2:$G$121,">0")) | F13: =COUNTIFS(Günlər!$A$2:$A$121,">="&A13,Günlər!$A$2:$A$121,"<"&(A13+7),Günlər!$C$2:$C$121,"Zal") | G13: =SUMIFS(Günlər!$D$2:$D$121,Günlər!$A$2:$A$121,">="&A13,Günlər!$A$2:$A$121,"<"&(A13+7)) | H13: =IF(COUNTIFS(Günlər!$A$2:$A$121,">="&A13,Günlər!$A$2:$A$121,"<"&(A13+7),Günlər!$N$2:$N$121,">0")<3,"",AVERAGEIFS(Günlər!$N$2:$N$121,Günlər!$A$2:$A$121,">="&A13,Günlər!$A$2:$A$121,"<"&(A13+7),Günlər!$N$2:$N$121,">0")) | I13: =IF(OR(H13="",H12=""),"",H13-H12) | J13: =IF(B13=0,"",IF(AND(I13<>"",I13<0.1),"Artım yavaşdır: Profil → artıq kaloriyə +150",IF(AND(I13<>"",I13>0.4),"Çox sürətli: Profil → artıq kaloridən −150",IF(C13<D13*0.9,"Az yeyirsən: hər gün +1 qəlyanaltı",IF(E13<Profil!$B$20*0.95,"Proteini artır","Əla, belə davam et")))))
A14: 46384 | B14: =COUNTIFS(Günlər!$A$2:$A$121,">="&A14,Günlər!$A$2:$A$121,"<"&(A14+7),Günlər!$G$2:$G$121,">0") | C14: =IF(B14=0,"",AVERAGEIFS(Günlər!$G$2:$G$121,Günlər!$A$2:$A$121,">="&A14,Günlər!$A$2:$A$121,"<"&(A14+7),Günlər!$G$2:$G$121,">0")) | D14: =IF(B14=0,"",AVERAGEIFS(Günlər!$F$2:$F$121,Günlər!$A$2:$A$121,">="&A14,Günlər!$A$2:$A$121,"<"&(A14+7),Günlər!$G$2:$G$121,">0")) | E14: =IF(B14=0,"",AVERAGEIFS(Günlər!$J$2:$J$121,Günlər!$A$2:$A$121,">="&A14,Günlər!$A$2:$A$121,"<"&(A14+7),Günlər!$G$2:$G$121,">0")) | F14: =COUNTIFS(Günlər!$A$2:$A$121,">="&A14,Günlər!$A$2:$A$121,"<"&(A14+7),Günlər!$C$2:$C$121,"Zal") | G14: =SUMIFS(Günlər!$D$2:$D$121,Günlər!$A$2:$A$121,">="&A14,Günlər!$A$2:$A$121,"<"&(A14+7)) | H14: =IF(COUNTIFS(Günlər!$A$2:$A$121,">="&A14,Günlər!$A$2:$A$121,"<"&(A14+7),Günlər!$N$2:$N$121,">0")<3,"",AVERAGEIFS(Günlər!$N$2:$N$121,Günlər!$A$2:$A$121,">="&A14,Günlər!$A$2:$A$121,"<"&(A14+7),Günlər!$N$2:$N$121,">0")) | I14: =IF(OR(H14="",H13=""),"",H14-H13) | J14: =IF(B14=0,"",IF(AND(I14<>"",I14<0.1),"Artım yavaşdır: Profil → artıq kaloriyə +150",IF(AND(I14<>"",I14>0.4),"Çox sürətli: Profil → artıq kaloridən −150",IF(C14<D14*0.9,"Az yeyirsən: hər gün +1 qəlyanaltı",IF(E14<Profil!$B$20*0.95,"Proteini artır","Əla, belə davam et")))))
... A19: 46419 | B19: =COUNTIFS(Günlər!$A$2:$A$121,">="&A19,Günlər!$A$2:$A$121,"<"&(A19+7),Günlər!$G$2:$G$121,">0") | C19: =IF(B19=0,"",AVERAGEIFS(Günlər!$G$2:$G$121,Günlər!$A$2:$A$121,">="&A19,Günlər!$A$2:$A$121,"<"&(A19+7),Günlər!$G$2:$G$121,">0")) | D19: =IF(B19=0,"",AVERAGEIFS(Günlər!$F$2:$F$121,Günlər!$A$2:$A$121,">="&A19,Günlər!$A$2:$A$121,"<"&(A19+7),Günlər!$G$2:$G$121,">0")) | E19: =IF(B19=0,"",AVERAGEIFS(Günlər!$J$2:$J$121,Günlər!$A$2:$A$121,">="&A19,Günlər!$A$2:$A$121,"<"&(A19+7),Günlər!$G$2:$G$121,">0")) | F19: =COUNTIFS(Günlər!$A$2:$A$121,">="&A19,Günlər!$A$2:$A$121,"<"&(A19+7),Günlər!$C$2:$C$121,"Zal") | G19: =SUMIFS(Günlər!$D$2:$D$121,Günlər!$A$2:$A$121,">="&A19,Günlər!$A$2:$A$121,"<"&(A19+7)) | H19: =IF(COUNTIFS(Günlər!$A$2:$A$121,">="&A19,Günlər!$A$2:$A$121,"<"&(A19+7),Günlər!$N$2:$N$121,">0")<3,"",AVERAGEIFS(Günlər!$N$2:$N$121,Günlər!$A$2:$A$121,">="&A19,Günlər!$A$2:$A$121,"<"&(A19+7),Günlər!$N$2:$N$121,">0")) | I19: =IF(OR(H19="",H18=""),"",H19-H18) | J19: =IF(B19=0,"",IF(AND(I19<>"",I19<0.1),"Artım yavaşdır: Profil → artıq kaloriyə +150",IF(AND(I19<>"",I19>0.4),"Çox sürətli: Profil → artıq kaloridən −150",IF(C19<D19*0.9,"Az yeyirsən: hər gün +1 qəlyanaltı",IF(E19<Profil!$B$20*0.95,"Proteini artır","Əla, belə davam et")))))

Sheet Menyu
A1: Gün | B1: Tip | C1: Yemək | D1: Saat | E1: Nə | F1: Məhsul | G1: Qram | H1: kkal | I1: Protein | J1: Karb. | K1: Yağ
A2: Bazar ertəsi | B2: Zal | C2: Səhər yeməyi | D2: 08:00 | E2: Yulaf sıyığı, banan, fıstıq pastası | F2: Yulaf yarması (fiocchi d'avena) | G2: 90 | H2: =ROUND(G2*INDEX('Qida bazası'!$D:$D,MATCH(F2,'Qida bazası'!$A:$A,0))/100,0) | I2: =ROUND(G2*INDEX('Qida bazası'!$E:$E,MATCH(F2,'Qida bazası'!$A:$A,0))/100,1) | J2: =ROUND(G2*INDEX('Qida bazası'!$F:$F,MATCH(F2,'Qida bazası'!$A:$A,0))/100,1) | K2: =ROUND(G2*INDEX('Qida bazası'!$G:$G,MATCH(F2,'Qida bazası'!$A:$A,0))/100,1)
F3: Süd 1,5% (latte parzialmente scremato) | G3: 300 | H3: =ROUND(G3*INDEX('Qida bazası'!$D:$D,MATCH(F3,'Qida bazası'!$A:$A,0))/100,0) | I3: =ROUND(G3*INDEX('Qida bazası'!$E:$E,MATCH(F3,'Qida bazası'!$A:$A,0))/100,1) | J3: =ROUND(G3*INDEX('Qida bazası'!$F:$F,MATCH(F3,'Qida bazası'!$A:$A,0))/100,1) | K3: =ROUND(G3*INDEX('Qida bazası'!$G:$G,MATCH(F3,'Qida bazası'!$A:$A,0))/100,1)
F4: Banan (banana) | G4: 120 | H4: =ROUND(G4*INDEX('Qida bazası'!$D:$D,MATCH(F4,'Qida bazası'!$A:$A,0))/100,0) | I4: =ROUND(G4*INDEX('Qida bazası'!$E:$E,MATCH(F4,'Qida bazası'!$A:$A,0))/100,1) | J4: =ROUND(G4*INDEX('Qida bazası'!$F:$F,MATCH(F4,'Qida bazası'!$A:$A,0))/100,1) | K4: =ROUND(G4*INDEX('Qida bazası'!$G:$G,MATCH(F4,'Qida bazası'!$A:$A,0))/100,1)
F5: Fıstıq pastası (burro d'arachidi) | G5: 15 | H5: =ROUND(G5*INDEX('Qida bazası'!$D:$D,MATCH(F5,'Qida bazası'!$A:$A,0))/100,0) | I5: =ROUND(G5*INDEX('Qida bazası'!$E:$E,MATCH(F5,'Qida bazası'!$A:$A,0))/100,1) | J5: =ROUND(G5*INDEX('Qida bazası'!$F:$F,MATCH(F5,'Qida bazası'!$A:$A,0))/100,1) | K5: =ROUND(G5*INDEX('Qida bazası'!$G:$G,MATCH(F5,'Qida bazası'!$A:$A,0))/100,1)
F6: Bal (miele) | G6: 10 | H6: =ROUND(G6*INDEX('Qida bazası'!$D:$D,MATCH(F6,'Qida bazası'!$A:$A,0))/100,0) | I6: =ROUND(G6*INDEX('Qida bazası'!$E:$E,MATCH(F6,'Qida bazası'!$A:$A,0))/100,1) | J6: =ROUND(G6*INDEX('Qida bazası'!$F:$F,MATCH(F6,'Qida bazası'!$A:$A,0))/100,1) | K6: =ROUND(G6*INDEX('Qida bazası'!$G:$G,MATCH(F6,'Qida bazası'!$A:$A,0))/100,1)
C7: Qəlyanaltı 1 | D7: 11:00 | E7: Yunan yoqurtu, bal, qoz | F7: Yunan yoqurtu 0% (yogurt greco 0%) | G7: 170 | H7: =ROUND(G7*INDEX('Qida bazası'!$D:$D,MATCH(F7,'Qida bazası'!$A:$A,0))/100,0) | I7: =ROUND(G7*INDEX('Qida bazası'!$E:$E,MATCH(F7,'Qida bazası'!$A:$A,0))/100,1) | J7: =ROUND(G7*INDEX('Qida bazası'!$F:$F,MATCH(F7,'Qida bazası'!$A:$A,0))/100,1) | K7: =ROUND(G7*INDEX('Qida bazası'!$G:$G,MATCH(F7,'Qida bazası'!$A:$A,0))/100,1)
F8: Bal (miele) | G8: 10 | H8: =ROUND(G8*INDEX('Qida bazası'!$D:$D,MATCH(F8,'Qida bazası'!$A:$A,0))/100,0) | I8: =ROUND(G8*INDEX('Qida bazası'!$E:$E,MATCH(F8,'Qida bazası'!$A:$A,0))/100,1) | J8: =ROUND(G8*INDEX('Qida bazası'!$F:$F,MATCH(F8,'Qida bazası'!$A:$A,0))/100,1) | K8: =ROUND(G8*INDEX('Qida bazası'!$G:$G,MATCH(F8,'Qida bazası'!$A:$A,0))/100,1)
F9: Qoz (noci) | G9: 15 | H9: =ROUND(G9*INDEX('Qida bazası'!$D:$D,MATCH(F9,'Qida bazası'!$A:$A,0))/100,0) | I9: =ROUND(G9*INDEX('Qida bazası'!$E:$E,MATCH(F9,'Qida bazası'!$A:$A,0))/100,1) | J9: =ROUND(G9*INDEX('Qida bazası'!$F:$F,MATCH(F9,'Qida bazası'!$A:$A,0))/100,1) | K9: =ROUND(G9*INDEX('Qida bazası'!$G:$G,MATCH(F9,'Qida bazası'!$A:$A,0))/100,1)
C10: Nahar | D10: 13:30 | E10: Toyuq, düyü, brokoli | F10: Toyuq döşü (çiy) (petto di pollo) | G10: 140 | H10: =ROUND(G10*INDEX('Qida bazası'!$D:$D,MATCH(F10,'Qida bazası'!$A:$A,0))/100,0) | I10: =ROUND(G10*INDEX('Qida bazası'!$E:$E,MATCH(F10,'Qida bazası'!$A:$A,0))/100,1) | J10: =ROUND(G10*INDEX('Qida bazası'!$F:$F,MATCH(F10,'Qida bazası'!$A:$A,0))/100,1) | K10: =ROUND(G10*INDEX('Qida bazası'!$G:$G,MATCH(F10,'Qida bazası'!$A:$A,0))/100,1)
F11: Düyü (çiy) (riso) | G11: 120 | H11: =ROUND(G11*INDEX('Qida bazası'!$D:$D,MATCH(F11,'Qida bazası'!$A:$A,0))/100,0) | I11: =ROUND(G11*INDEX('Qida bazası'!$E:$E,MATCH(F11,'Qida bazası'!$A:$A,0))/100,1) | J11: =ROUND(G11*INDEX('Qida bazası'!$F:$F,MATCH(F11,'Qida bazası'!$A:$A,0))/100,1) | K11: =ROUND(G11*INDEX('Qida bazası'!$G:$G,MATCH(F11,'Qida bazası'!$A:$A,0))/100,1)
F12: Brokoli (broccoli) | G12: 150 | H12: =ROUND(G12*INDEX('Qida bazası'!$D:$D,MATCH(F12,'Qida bazası'!$A:$A,0))/100,0) | I12: =ROUND(G12*INDEX('Qida bazası'!$E:$E,MATCH(F12,'Qida bazası'!$A:$A,0))/100,1) | J12: =ROUND(G12*INDEX('Qida bazası'!$F:$F,MATCH(F12,'Qida bazası'!$A:$A,0))/100,1) | K12: =ROUND(G12*INDEX('Qida bazası'!$G:$G,MATCH(F12,'Qida bazası'!$A:$A,0))/100,1)
F13: Zeytun yağı (olio extravergine) | G13: 10 | H13: =ROUND(G13*INDEX('Qida bazası'!$D:$D,MATCH(F13,'Qida bazası'!$A:$A,0))/100,0) | I13: =ROUND(G13*INDEX('Qida bazası'!$E:$E,MATCH(F13,'Qida bazası'!$A:$A,0))/100,1) | J13: =ROUND(G13*INDEX('Qida bazası'!$F:$F,MATCH(F13,'Qida bazası'!$A:$A,0))/100,1) | K13: =ROUND(G13*INDEX('Qida bazası'!$G:$G,MATCH(F13,'Qida bazası'!$A:$A,0))/100,1)
C14: Qəlyanaltı 2 | D14: 17:00 | E14: Bresaola ilə panino, alma | F14: Tam taxıl çörək (pane integrale) | G14: 80 | H14: =ROUND(G14*INDEX('Qida bazası'!$D:$D,MATCH(F14,'Qida bazası'!$A:$A,0))/100,0) | I14: =ROUND(G14*INDEX('Qida bazası'!$E:$E,MATCH(F14,'Qida bazası'!$A:$A,0))/100,1) | J14: =ROUND(G14*INDEX('Qida bazası'!$F:$F,MATCH(F14,'Qida bazası'!$A:$A,0))/100,1) | K14: =ROUND(G14*INDEX('Qida bazası'!$G:$G,MATCH(F14,'Qida bazası'!$A:$A,0))/100,1)
F15: Bresaola (bresaola) | G15: 40 | H15: =ROUND(G15*INDEX('Qida bazası'!$D:$D,MATCH(F15,'Qida bazası'!$A:$A,0))/100,0) | I15: =ROUND(G15*INDEX('Qida bazası'!$E:$E,MATCH(F15,'Qida bazası'!$A:$A,0))/100,1) | J15: =ROUND(G15*INDEX('Qida bazası'!$F:$F,MATCH(F15,'Qida bazası'!$A:$A,0))/100,1) | K15: =ROUND(G15*INDEX('Qida bazası'!$G:$G,MATCH(F15,'Qida bazası'!$A:$A,0))/100,1)
F16: Alma (mela) | G16: 180 | H16: =ROUND(G16*INDEX('Qida bazası'!$D:$D,MATCH(F16,'Qida bazası'!$A:$A,0))/100,0) | I16: =ROUND(G16*INDEX('Qida bazası'!$E:$E,MATCH(F16,'Qida bazası'!$A:$A,0))/100,1) | J16: =ROUND(G16*INDEX('Qida bazası'!$F:$F,MATCH(F16,'Qida bazası'!$A:$A,0))/100,1) | K16: =ROUND(G16*INDEX('Qida bazası'!$G:$G,MATCH(F16,'Qida bazası'!$A:$A,0))/100,1)
C17: Şam yeməyi | D17: 20:30 | E17: Tuna və pomidor sousu ilə makaron, salat | F17: Makaron (çiy) (pasta di semola) | G17: 110 | H17: =ROUND(G17*INDEX('Qida bazası'!$D:$D,MATCH(F17,'Qida bazası'!$A:$A,0))/100,0) | I17: =ROUND(G17*INDEX('Qida bazası'!$E:$E,MATCH(F17,'Qida bazası'!$A:$A,0))/100,1) | J17: =ROUND(G17*INDEX('Qida bazası'!$F:$F,MATCH(F17,'Qida bazası'!$A:$A,0))/100,1) | K17: =ROUND(G17*INDEX('Qida bazası'!$G:$G,MATCH(F17,'Qida bazası'!$A:$A,0))/100,1)
F18: Tuna, öz suyunda (tonno al naturale) | G18: 80 | H18: =ROUND(G18*INDEX('Qida bazası'!$D:$D,MATCH(F18,'Qida bazası'!$A:$A,0))/100,0) | I18: =ROUND(G18*INDEX('Qida bazası'!$E:$E,MATCH(F18,'Qida bazası'!$A:$A,0))/100,1) | J18: =ROUND(G18*INDEX('Qida bazası'!$F:$F,MATCH(F18,'Qida bazası'!$A:$A,0))/100,1) | K18: =ROUND(G18*INDEX('Qida bazası'!$G:$G,MATCH(F18,'Qida bazası'!$A:$A,0))/100,1)
F19: Pomidor sousu (passata di pomodoro) | G19: 150 | H19: =ROUND(G19*INDEX('Qida bazası'!$D:$D,MATCH(F19,'Qida bazası'!$A:$A,0))/100,0) | I19: =ROUND(G19*INDEX('Qida bazası'!$E:$E,MATCH(F19,'Qida bazası'!$A:$A,0))/100,1) | J19: =ROUND(G19*INDEX('Qida bazası'!$F:$F,MATCH(F19,'Qida bazası'!$A:$A,0))/100,1) | K19: =ROUND(G19*INDEX('Qida bazası'!$G:$G,MATCH(F19,'Qida bazası'!$A:$A,0))/100,1)
F20: Zeytun yağı (olio extravergine) | G20: 10 | H20: =ROUND(G20*INDEX('Qida bazası'!$D:$D,MATCH(F20,'Qida bazası'!$A:$A,0))/100,0) | I20: =ROUND(G20*INDEX('Qida bazası'!$E:$E,MATCH(F20,'Qida bazası'!$A:$A,0))/100,1) | J20: =ROUND(G20*INDEX('Qida bazası'!$F:$F,MATCH(F20,'Qida bazası'!$A:$A,0))/100,1) | K20: =ROUND(G20*INDEX('Qida bazası'!$G:$G,MATCH(F20,'Qida bazası'!$A:$A,0))/100,1)
F21: Yaşıl salat (insalata) | G21: 80 | H21: =ROUND(G21*INDEX('Qida bazası'!$D:$D,MATCH(F21,'Qida bazası'!$A:$A,0))/100,0) | I21: =ROUND(G21*INDEX('Qida bazası'!$E:$E,MATCH(F21,'Qida bazası'!$A:$A,0))/100,1) | J21: =ROUND(G21*INDEX('Qida bazası'!$F:$F,MATCH(F21,'Qida bazası'!$A:$A,0))/100,1) | K21: =ROUND(G21*INDEX('Qida bazası'!$G:$G,MATCH(F21,'Qida bazası'!$A:$A,0))/100,1)
